Workbook

Sheet الإعدادات
A1: الإعدادات — القوائم ودليل الحسابات وقواعد الرواتب
A2: الخانات الصفراء فقط هي اللي بتتعدل — كل الشيتات التانية بتقرا منها
A3: أنواع مصروفات الدرج | C3: الموظف | D3: الراتب الأساسي | E3: بدل المواصلات | G3: الكود | H3: الحساب | I3: التصنيف العام | J3: الطبيعة | K3: القائمة | M3: القاعدة | N3: القيمة
A4: سلفة | C4: أحمد | D4: 3000 | E4: 300 | G4: 4100 | H4: مبيعات الخدمات | I4: الإيرادات | J4: إيراد | K4: قائمة الدخل | M4: نسبة ضريبة القيمة المضافة | N4: 0.15
A5: مستلزمات | C5: خالد | D5: 2800 | E5: 300 | G5: 5100 | H5: الرواتب والبدلات | I5: مصاريف الموظفين | J5: مصروف | K5: قائمة الدخل | M5: حد بداية العمولة (ريال مبيعات) | N5: 3000
A6: مواصلات | C6: يوسف | D6: 2800 | E6: 300 | G6: 5110 | H6: العمولات والحوافز | I6: مصاريف الموظفين | J6: مصروف | K6: قائمة الدخل | M6: نسبة العمولة فوق الحد | N6: 0.3
A7: ضيافة | C7: سامي | D7: 2500 | E7: 250 | G7: 5120 | H7: تكاليف الموظفين (تأشيرات وتأمين) | I7: مصاريف الموظفين | J7: مصروف | K7: قائمة الدخل | M7: تارجت مكافأة المبيعات | N7: 10000
C8: فارس | D8: 2500 | E8: 250 | G8: 5200 | H8: الإيجار | I8: مصاريف الفرع | J8: مصروف | K8: قائمة الدخل | M8: قيمة مكافأة التارجت | N8: 300
C9: ماجد | D9: 2200 | E9: 200 | G9: 5210 | H9: الكهرباء والمياه | I9: مصاريف الفرع | J9: مصروف | K9: قائمة الدخل | M9: سعر ساعة الأوفر تايم | N9: 20
G10: 5220 | H10: المستلزمات والأدوات | I10: مصاريف التشغيل | J10: مصروف | K10: قائمة الدخل | M10: أيام الشهر لحساب اليومية | N10: 30
G11: 5230 | H11: الصيانة والإصلاحات | I11: مصاريف الفرع | J11: مصروف | K11: قائمة الدخل
G12: 5300 | H12: التسويق | I12: مصاريف التشغيل | J12: مصروف | K12: قائمة الدخل
G13: 5400 | H13: رسوم بوابات الدفع | I13: مصاريف التشغيل | J13: مصروف | K13: قائمة الدخل
G14: 5900 | H14: مصروفات نثرية من الدرج | I14: مصاريف التشغيل | J14: مصروف | K14: قائمة الدخل
G15: 2300 | H15: ضريبة القيمة المضافة المسددة | I15: الالتزامات | J15: تسوية | K15: المركز المالي

Sheet اليومية
A1: اليومية — مبيعات ومصروفات الدرج ومطابقة الكاش
A2: الكاشير بيدخل الخانات الصفراء بس — الإجماليات والمطابقة والصافي محسوبين
A3: اليوم | D3: مصروفات من الدرج | Q3: المبيعات حسب طريقة الدفع (من النظام) | W3: مطابقة الفعلي
A4: التاريخ | B4: اليوم | C4: الشهر | D4: نوع 1 | E4: الموظف 1 | F4: القيمة 1 | G4: نوع 2 | H4: الموظف 2 | I4: القيمة 2 | J4: نوع 3 | K4: الموظف 3 | L4: القيمة 3 | M4: نوع 4 | N4: الموظف 4 | O4: القيمة 4 | P4: إجمالي المصروفات | Q4: الشبكة | R4: الكاش | S4: الأونلاين | T4: تابي | U4: تمارا | V4: إجمالي المبيعات | W4: الشبكة الفعلي | X4: الكاش الفعلي | Y4: فرق الشبكة | Z4: فرق الكاش | AA4: الحالة | AB4: صافي اليوم
A5: 46204 | B5: الأربعاء | C5: يوليو 2026 | D5: مستلزمات | F5: 50 | G5: مواصلات | I5: 58 | J5: مواصلات | L5: 31 | P5: =F5+I5+L5+O5 -> 139 | Q5: 1991 | R5: 877 | T5: 350 | U5: 257 | V5: =SUM(Q5:U5) -> 3475 | W5: 1991 | X5: 738 | Y5: =W5-Q5 -> 0 | Z5: =X5-(R5-P5) -> 0 | AA5: =IF(AND(Y5=0,Z5=0),"مطابق",IF(Y5+Z5>0,"زيادة","عجز")) -> مطابق | AB5: =V5-P5 -> 3336
A6: 46205 | B6: الخميس | C6: يوليو 2026 | D6: مواصلات | F6: 44 | P6: =F6+I6+L6+O6 -> 44 | Q6: 3807 | R6: 1437 | S6: 110 | T6: 196 | V6: =SUM(Q6:U6) -> 5550 | W6: 3807 | X6: 1410 | Y6: =W6-Q6 -> 0 | Z6: =X6-(R6-P6) -> 17 | AA6: =IF(AND(Y6=0,Z6=0),"مطابق",IF(Y6+Z6>0,"زيادة","عجز")) -> زيادة | AB6: =V6-P6 -> 5506
A7: 46206 | B7: الجمعة | C7: يوليو 2026 | D7: مستلزمات | F7: 36 | G7: مواصلات | I7: 60 | P7: =F7+I7+L7+O7 -> 96 | Q7: 4303 | R7: 1096 | S7: 353 | T7: 348 | V7: =SUM(Q7:U7) -> 6100 | W7: 4303 | X7: 1000 | Y7: =W7-Q7 -> 0 | Z7: =X7-(R7-P7) -> 0 | AA7: =IF(AND(Y7=0,Z7=0),"مطابق",IF(Y7+Z7>0,"زيادة","عجز")) -> مطابق | AB7: =V7-P7 -> 6004
A8: 46207 | B8: السبت | C8: يوليو 2026 | D8: مواصلات | F8: 42 | G8: مستلزمات | I8: 32 | J8: مواصلات | L8: 38 | P8: =F8+I8+L8+O8 -> 112 | Q8: 2166 | R8: 1203 | V8: =SUM(Q8:U8) -> 3369 | W8: 2166 | X8: 1091 | Y8: =W8-Q8 -> 0 | Z8: =X8-(R8-P8) -> 0 | AA8: =IF(AND(Y8=0,Z8=0),"مطابق",IF(Y8+Z8>0,"زيادة","عجز")) -> مطابق | AB8: =V8-P8 -> 3257
A9: 46208 | B9: الأحد | C9: يوليو 2026 | D9: مواصلات | F9: 26 | G9: مواصلات | I9: 56 | P9: =F9+I9+L9+O9 -> 82 | Q9: 3027 | R9: 873 | S9: 228 | V9: =SUM(Q9:U9) -> 4128 | W9: 3027 | X9: 791 | Y9: =W9-Q9 -> 0 | Z9: =X9-(R9-P9) -> 0 | AA9: =IF(AND(Y9=0,Z9=0),"مطابق",IF(Y9+Z9>0,"زيادة","عجز")) -> مطابق | AB9: =V9-P9 -> 4046
A10: 46209 | B10: الاثنين | C10: يوليو 2026 | D10: سلفة | E10: أحمد | F10: 200 | P10: =F10+I10+L10+O10 -> 200 | Q10: 3171 | R10: 574 | V10: =SUM(Q10:U10) -> 3745 | W10: 3171 | X10: 400 | Y10: =W10-Q10 -> 0 | Z10: =X10-(R10-P10) -> 26 | AA10: =IF(AND(Y10=0,Z10=0),"مطابق",IF(Y10+Z10>0,"زيادة","عجز")) -> زيادة | AB10: =V10-P10 -> 3545
A11: 46210 | B11: الثلاثاء | C11: يوليو 2026 | D11: مستلزمات | F11: 64 | P11: =F11+I11+L11+O11 -> 64 | Q11: 3282 | R11: 1182 | T11: 262 | V11: =SUM(Q11:U11) -> 4726 | W11: 3282 | X11: 1118 | Y11: =W11-Q11 -> 0 | Z11: =X11-(R11-P11) -> 0 | AA11: =IF(AND(Y11=0,Z11=0),"مطابق",IF(Y11+Z11>0,"زيادة","عجز")) -> مطابق | AB11: =V11-P11 -> 4662
A12: 46211 | B12: الأربعاء | C12: يوليو 2026 | D12: مستلزمات | F12: 36 | G12: مستلزمات | I12: 145 | J12: سلفة | K12: سامي | L12: 150 | P12: =F12+I12+L12+O12 -> 331 | Q12: 2632 | R12: 617 | V12: =SUM(Q12:U12) -> 3249 | W12: 2632 | X12: 304 | Y12: =W12-Q12 -> 0 | Z12: =X12-(R12-P12) -> 18 | AA12: =IF(AND(Y12=0,Z12=0),"مطابق",IF(Y12+Z12>0,"زيادة","عجز")) -> زيادة | AB12: =V12-P12 -> 2918
A13: 46212 | B13: الخميس | C13: يوليو 2026 | D13: مواصلات | F13: 60 | G13: ضيافة | I13: 77 | P13: =F13+I13+L13+O13 -> 137 | Q13: 3722 | R13: 1386 | V13: =SUM(Q13:U13) -> 5108 | W13: 3722 | X13: 1249 | Y13: =W13-Q13 -> 0 | Z13: =X13-(R13-P13) -> 0 | AA13: =IF(AND(Y13=0,Z13=0),"مطابق",IF(Y13+Z13>0,"زيادة","عجز")) -> مطابق | AB13: =V13-P13 -> 4971
A14: 46213 | B14: الجمعة | C14: يوليو 2026 | D14: مستلزمات | F14: 113 | G14: مستلزمات | I14: 54 | P14: =F14+I14+L14+O14 -> 167 | Q14: 3349 | R14: 1083 | U14: 153 | V14: =SUM(Q14:U14) -> 4585 | W14: 3349 | X14: 916 | Y14: =W14-Q14 -> 0 | Z14: =X14-(R14-P14) -> 0 | AA14: =IF(AND(Y14=0,Z14=0),"مطابق",IF(Y14+Z14>0,"زيادة","عجز")) -> مطابق | AB14: =V14-P14 -> 4418
A15: 46214 | B15: السبت | C15: يوليو 2026 | D15: مستلزمات | F15: 58 | G15: مستلزمات | I15: 105 | P15: =F15+I15+L15+O15 -> 163 | Q15: 2453 | R15: 1116 | S15: 369 | V15: =SUM(Q15:U15) -> 3938 | W15: 2453 | X15: 953 | Y15: =W15-Q15 -> 0 | Z15: =X15-(R15-P15) -> 0 | AA15: =IF(AND(Y15=0,Z15=0),"مطابق",IF(Y15+Z15>0,"زيادة","عجز")) -> مطابق | AB15: =V15-P15 -> 3775
A16: 46215 | B16: الأحد | C16: يوليو 2026 | D16: مستلزمات | F16: 104 | G16: مستلزمات | I16: 33 | J16: ضيافة | L16: 23 | P16: =F16+I16+L16+O16 -> 160 | Q16: 1954 | R16: 821 | V16: =SUM(Q16:U16) -> 2775 | W16: 1954 | X16: 661 | Y16: =W16-Q16 -> 0 | Z16: =X16-(R16-P16) -> 0 | AA16: =IF(AND(Y16=0,Z16=0),"مطابق",IF(Y16+Z16>0,"زيادة","عجز")) -> مطابق | AB16: =V16-P16 -> 2615
A17: 46216 | B17: الاثنين | C17: يوليو 2026 | D17: مستلزمات | F17: 148 | G17: ضيافة | I17: 79 | P17: =F17+I17+L17+O17 -> 227 | Q17: 1950 | R17: 927 | T17: 202 | V17: =SUM(Q17:U17) -> 3079 | W17: 1950 | X17: 700 | Y17: =W17-Q17 -> 0 | Z17: =X17-(R17-P17) -> 0 | AA17: =IF(AND(Y17=0,Z17=0),"مطابق",IF(Y17+Z17>0,"زيادة","عجز")) -> مطابق | AB17: =V17-P17 -> 2852
A18: 46217 | B18: الثلاثاء | C18: يوليو 2026 | D18: مواصلات | F18: 49 | G18: سلفة | H18: أحمد | I18: 100 | P18: =F18+I18+L18+O18 -> 149 | Q18: 2370 | R18: 1075 | V18: =SUM(Q18:U18) -> 3445 | W18: 2370 | X18: 926 | Y18: =W18-Q18 -> 0 | Z18: =X18-(R18-P18) -> 0 | AA18: =IF(AND(Y18=0,Z18=0),"مطابق",IF(Y18+Z18>0,"زيادة","عجز")) -> مطابق | AB18: =V18-P18 -> 3296
A19: 46218 | B19: الأربعاء | C19: يوليو 2026 | D19: مواصلات | F19: 26 | P19: =F19+I19+L19+O19 -> 26 | Q19: 2755 | R19: 1277 | U19: 183 | V19: =SUM(Q19:U19) -> 4215 | W19: 2755 | X19: 1212 | Y19: =W19-Q19 -> 0 | Z19: =X19-(R19-P19) -> -39 | AA19: =IF(AND(Y19=0,Z19=0),"مطابق",IF(Y19+Z19>0,"زيادة","عجز")) -> عجز | AB19: =V19-P19 -> 4189
A20: 46219 | B20: الخميس | C20: يوليو 2026 | D20: ضيافة | F20: 22 | P20: =F20+I20+L20+O20 -> 22 | Q20: 3287 | R20: 900 | T20: 124 | V20: =SUM(Q20:U20) -> 4311 | W20: 3287 | X20: 878 | Y20: =W20-Q20 -> 0 | Z20: =X20-(R20-P20) -> 0 | AA20: =IF(AND(Y20=0,Z20=0),"مطابق",IF(Y20+Z20>0,"زيادة","عجز")) -> مطابق | AB20: =V20-P20 -> 4289
A21: 46220 | B21: الجمعة | C21: يوليو 2026 | D21: مستلزمات | F21: 132 | G21: ضيافة | I21: 75 | J21: سلفة | K21: يوسف | L21: 300 | P21: =F21+I21+L21+O21 -> 507 | Q21: 4060 | R21: 972 | V21: =SUM(Q21:U21) -> 5032 | W21: 4060 | X21: 495 | Y21: =W21-Q21 -> 0 | Z21: =X21-(R21-P21) -> 30 | AA21: =IF(AND(Y21=0,Z21=0),"مطابق",IF(Y21+Z21>0,"زيادة","عجز")) -> زيادة | AB21: =V21-P21 -> 4525
A22: 46221 | B22: السبت | C22: يوليو 2026 | D22: مستلزمات | F22: 65 | P22: =F22+I22+L22+O22 -> 65 | Q22: 2053 | R22: 799 | T22: 367 | V22: =SUM(Q22:U22) -> 3219 | W22: 2053 | X22: 700 | Y22: =W22-Q22 -> 0 | Z22: =X22-(R22-P22) -> -34 | AA22: =IF(AND(Y22=0,Z22=0),"مطابق",IF(Y22+Z22>0,"زيادة","عجز")) -> عجز | AB22: =V22-P22 -> 3154
A23: 46222 | B23: الأحد | C23: يوليو 2026 | D23: سلفة | E23: سامي | F23: 200 | P23: =F23+I23+L23+O23 -> 200 | Q23: 3158 | R23: 945 | V23: =SUM(Q23:U23) -> 4103 | W23: 3158 | X23: 745 | Y23: =W23-Q23 -> 0 | Z23: =X23-(R23-P23) -> 0 | AA23: =IF(AND(Y23=0,Z23=0),"مطابق",IF(Y23+Z23>0,"زيادة","عجز")) -> مطابق | AB23: =V23-P23 -> 3903
A24: 46223 | B24: الاثنين | C24: يوليو 2026 | D24: سلفة | E24: فارس | F24: 100 | G24: سلفة | H24: أحمد | I24: 100 | J24: مستلزمات | L24: 69 | P24: =F24+I24+L24+O24 -> 269 | Q24: 2257 | R24: 564 | S24: 212 | T24: 284 | V24: =SUM(Q24:U24) -> 3317 | W24: 2257 | X24: 295 | Y24: =W24-Q24 -> 0 | Z24: =X24-(R24-P24) -> 0 | AA24: =IF(AND(Y24=0,Z24=0),"مطابق",IF(Y24+Z24>0,"زيادة","عجز")) -> مطابق | AB24: =V24-P24 -> 3048
A25: 46224 | B25: الثلاثاء | C25: يوليو 2026 | D25: مستلزمات | F25: 121 | P25: =F25+I25+L25+O25 -> 121 | Q25: 1972 | R25: 1162 | U25: 170 | V25: =SUM(Q25:U25) -> 3304 | W25: 1972 | X25: 1041 | Y25: =W25-Q25 -> 0 | Z25: =X25-(R25-P25) -> 0 | AA25: =IF(AND(Y25=0,Z25=0),"مطابق",IF(Y25+Z25>0,"زيادة","عجز")) -> مطابق | AB25: =V25-P25 -> 3183
A26: 46225 | B26: الأربعاء | C26: يوليو 2026 | D26: مستلزمات | F26: 156 | G26: سلفة | H26: سامي | I26: 150 | P26: =F26+I26+L26+O26 -> 306 | Q26: 3046 | R26: 525 | U26: 134 | V26: =SUM(Q26:U26) -> 3705 | W26: 3046 | X26: 219 | Y26: =W26-Q26 -> 0 | Z26: =X26-(R26-P26) -> 0 | AA26: =IF(AND(Y26=0,Z26=0),"مطابق",IF(Y26+Z26>0,"زيادة","عجز")) -> مطابق | AB26: =V26-P26 -> 3399
A27: 46226 | B27: الخميس | C27: يوليو 2026 | D27: مواصلات | F27: 51 | G27: مواصلات | I27: 50 | J27: مستلزمات | L27: 116 | P27: =F27+I27+L27+O27 -> 217 | Q27: 2685 | R27: 913 | V27: =SUM(Q27:U27) -> 3598 | W27: 2685 | X27: 687 | Y27: =W27-Q27 -> 0 | Z27: =X27-(R27-P27) -> -9 | AA27: =IF(AND(Y27=0,Z27=0),"مطابق",IF(Y27+Z27>0,"زيادة","عجز")) -> عجز | AB27: =V27-P27 -> 3381
A28: 46227 | B28: الجمعة | C28: يوليو 2026 | D28: مستلزمات | F28: 151 | P28: =F28+I28+L28+O28 -> 151 | Q28: 3347 | R28: 1351 | V28: =SUM(Q28:U28) -> 4698 | W28: 3347 | X28: 1200 | Y28: =W28-Q28 -> 0 | Z28: =X28-(R28-P28) -> 0 | AA28: =IF(AND(Y28=0,Z28=0),"مطابق",IF(Y28+Z28>0,"زيادة","عجز")) -> مطابق | AB28: =V28-P28 -> 4547
A29: 46228 | B29: السبت | C29: يوليو 2026 | D29: مستلزمات | F29: 32 | P29: =F29+I29+L29+O29 -> 32 | Q29: 2857 | R29: 1251 | V29: =SUM(Q29:U29) -> 4108 | W29: 2857 | X29: 1219 | Y29: =W29-Q29 -> 0 | Z29: =X29-(R29-P29) -> 0 | AA29: =IF(AND(Y29=0,Z29=0),"مطابق",IF(Y29+Z29>0,"زيادة","عجز")) -> مطابق | AB29: =V29-P29 -> 4076
A30: 46229 | B30: الأحد | C30: يوليو 2026 | D30: سلفة | E30: فارس | F30: 150 | G30: مستلزمات | I30: 111 | P30: =F30+I30+L30+O30 -> 261 | Q30: 2877 | R30: 1050 | V30: =SUM(Q30:U30) -> 3927 | W30: 2877 | X30: 789 | Y30: =W30-Q30 -> 0 | Z30: =X30-(R30-P30) -> 0 | AA30: =IF(AND(Y30=0,Z30=0),"مطابق",IF(Y30+Z30>0,"زيادة","عجز")) -> مطابق | AB30: =V30-P30 -> 3666
A31: 46230 | B31: الاثنين | C31: يوليو 2026 | D31: مواصلات | F31: 28 | G31: سلفة | H31: سامي | I31: 100 | J31: مواصلات | L31: 54 | P31: =F31+I31+L31+O31 -> 182 | Q31: 1859 | R31: 867 | T31: 186 | V31: =SUM(Q31:U31) -> 2912 | W31: 1859 | X31: 706 | Y31: =W31-Q31 -> 0 | Z31: =X31-(R31-P31) -> 21 | AA31: =IF(AND(Y31=0,Z31=0),"مطابق",IF(Y31+Z31>0,"زيادة","عجز")) -> زيادة | AB31: =V31-P31 -> 2730
A32: 46231 | B32: الثلاثاء | C32: يوليو 2026 | D32: سلفة | E32: فارس | F32: 150 | G32: سلفة | H32: فارس | I32: 150 | J32: مواصلات | L32: 50 | P32: =F32+I32+L32+O32 -> 350 | Q32: 2309 | R32: 739 | S32: 142 | U32: 252 | V32: =SUM(Q32:U32) -> 3442 | W32: 2309 | X32: 389 | Y32: =W32-Q32 -> 0 | Z32: =X32-(R32-P32) -> 0 | AA32: =IF(AND(Y32=0,Z32=0),"مطابق",IF(Y32+Z32>0,"زيادة","عجز")) -> مطابق | AB32: =V32-P32 -> 3092
A33: 46232 | B33: الأربعاء | C33: يوليو 2026 | D33: مواصلات | F33: 26 | G33: مستلزمات | I33: 62 | J33: سلفة | K33: أحمد | L33: 150 | P33: =F33+I33+L33+O33 -> 238 | Q33: 2962 | R33: 611 | S33: 286 | V33: =SUM(Q33:U33) -> 3859 | W33: 2962 | X33: 373 | Y33: =W33-Q33 -> 0 | Z33: =X33-(R33-P33) -> 0 | AA33: =IF(AND(Y33=0,Z33=0),"مطابق",IF(Y33+Z33>0,"زيادة","عجز")) -> مطابق | AB33: =V33-P33 -> 3621
A34: 46233 | B34: الخميس | C34: يوليو 2026 | D34: مستلزمات | F34: 31 | G34: مستلزمات | I34: 114 | J34: مستلزمات | L34: 138 | P34: =F34+I34+L34+O34 -> 283 | Q34: 3541 | R34: 1627 | S34: 111 | V34: =SUM(Q34:U34) -> 5279 | W34: 3541 | X34: 1344 | Y34: =W34-Q34 -> 0 | Z34: =X34-(R34-P34) -> 0 | AA34: =IF(AND(Y34=0,Z34=0),"مطابق",IF(Y34+Z34>0,"زيادة","عجز")) -> مطابق | AB34: =V34-P34 -> 4996
A35: 46234 | B35: الجمعة | C35: يوليو 2026 | D35: مواصلات | F35: 20 | G35: ضيافة | I35: 42 | P35: =F35+I35+L35+O35 -> 62 | Q35: 4521 | R35: 852 | T35: 307 | V35: =SUM(Q35:U35) -> 5680 | W35: 4521 | X35: 790 | Y35: =W35-Q35 -> 0 | Z35: =X35-(R35-P35) -> 0 | AA35: =IF(AND(Y35=0,Z35=0),"مطابق",IF(Y35+Z35>0,"زيادة","عجز")) -> مطابق | AB35: =V35-P35 -> 5618
A36: 46235 | B36: السبت | C36: أغسطس 2026 | D36: مواصلات | F36: 45 | G36: مستلزمات | I36: 120 | P36: =F36+I36+L36+O36 -> 165 | Q36: 2494 | R36: 1215 | V36: =SUM(Q36:U36) -> 3709 | W36: 2494 | X36: 1050 | Y36: =W36-Q36 -> 0 | Z36: =X36-(R36-P36) -> 0 | AA36: =IF(AND(Y36=0,Z36=0),"مطابق",IF(Y36+Z36>0,"زيادة","عجز")) -> مطابق | AB36: =V36-P36 -> 3544
A37: 46236 | B37: الأحد | C37: أغسطس 2026 | D37: مستلزمات | F37: 100 | G37: سلفة | H37: أحمد | I37: 100 | P37: =F37+I37+L37+O37 -> 200 | Q37: 3351 | R37: 838 | S37: 287 | V37: =SUM(Q37:U37) -> 4476 | W37: 3351 | X37: 668 | Y37: =W37-Q37 -> 0 | Z37: =X37-(R37-P37) -> 30 | AA37: =IF(AND(Y37=0,Z37=0),"مطابق",IF(Y37+Z37>0,"زيادة","عجز")) -> زيادة | AB37: =V37-P37 -> 4276
A38: 46237 | B38: الاثنين | C38: أغسطس 2026 | D38: ضيافة | F38: 65 | P38: =F38+I38+L38+O38 -> 65 | Q38: 2566 | R38: 469 | T38: 127 | V38: =SUM(Q38:U38) -> 3162 | W38: 2566 | X38: 404 | Y38: =W38-Q38 -> 0 | Z38: =X38-(R38-P38) -> 0 | AA38: =IF(AND(Y38=0,Z38=0),"مطابق",IF(Y38+Z38>0,"زيادة","عجز")) -> مطابق | AB38: =V38-P38 -> 3097
A39: 46238 | B39: الثلاثاء | C39: أغسطس 2026 | D39: مستلزمات | F39: 78 | P39: =F39+I39+L39+O39 -> 78 | Q39: 2947 | R39: 848 | U39: 184 | V39: =SUM(Q39:U39) -> 3979 | W39: 2947 | X39: 770 | Y39: =W39-Q39 -> 0 | Z39: =X39-(R39-P39) -> 0 | AA39: =IF(AND(Y39=0,Z39=0),"مطابق",IF(Y39+Z39>0,"زيادة","عجز")) -> مطابق | AB39: =V39-P39 -> 3901
A40: 46239 | B40: الأربعاء | C40: أغسطس 2026 | D40: مواصلات | F40: 53 | G40: مستلزمات | I40: 124 | P40: =F40+I40+L40+O40 -> 177 | Q40: 1826 | R40: 1254 | V40: =SUM(Q40:U40) -> 3080 | W40: 1826 | X40: 1077 | Y40: =W40-Q40 -> 0 | Z40: =X40-(R40-P40) -> 0 | AA40: =IF(AND(Y40=0,Z40=0),"مطابق",IF(Y40+Z40>0,"زيادة","عجز")) -> مطابق | AB40: =V40-P40 -> 2903
...

Sheet الرواتب
A1: الرواتب الشهرية
A2: العمولة والمكافأة والأوفر تايم من قواعد الإعدادات — السلف بتتسحب أوتوماتيك من اليومية
A4: السنة | B4: الشهر | C4: الموظف | D4: الأساسي | E4: المواصلات | F4: مبيعات الموظف | G4: العمولة | H4: مكافأة التارجت | I4: ساعات أوفر تايم | J4: بدل الأوفر تايم | K4: تسوية يدوية | L4: إجمالي المستحقات | M4: أيام غياب | N4: خصم الغياب | O4: سلف من الدرج | P4: إجمالي الخصومات | Q4: صافي الراتب
A5: 2026 | B5: يوليو 2026 | C5: أحمد | D5: =INDEX(الإعدادات!$D$4:$D$9,MATCH(C5,الإعدادات!$C$4:$C$9,0)) -> 3000 | E5: =INDEX(الإعدادات!$E$4:$E$9,MATCH(C5,الإعدادات!$C$4:$C$9,0)) -> 300 | F5: 10379 | G5: =MAX(0,F5-الإعدادات!$N$5)*الإعدادات!$N$6 -> 2213.7 | H5: =IF(F5>=الإعدادات!$N$7,الإعدادات!$N$8,0) -> 300 | I5: 8 | J5: =I5*الإعدادات!$N$9 -> 160 | L5: =D5+E5+G5+H5+J5+K5 -> 5973.7 | N5: =M5*D5/الإعدادات!$N$10 -> 0 | O5: =SUMIFS(اليومية!$F$5:$F$96,اليومية!$D$5:$D$96,"سلفة",اليومية!$E$5:$E$96,$C5,اليومية!$C$5:$C$96,$B5)+SUMIFS(اليومية!$I$5:$I$96,اليومية!$G$5:$G$96,"سلفة",اليومية!$H$5:$H$96,$C5,اليومية!$C$5:$C$96,$B5)+SUMIFS(اليومية!$L$5:$L$96,اليومية!$J$5:$J$96,"سلفة",اليومية!$K$5:$K$96,$C5,اليومية!$C$5:$C$96,$B5)+SUMIFS(اليومية!$O$5:$O$96,اليومية!$M$5:$M$96,"سلفة",اليومية!$N$5:$N$96,$C5,اليومية!$C$5:$C$96,$B5) -> 550 | P5: =N5+O5 -> 550 | Q5: =L5-P5 -> 5423.7
A6: 2026 | B6: يوليو 2026 | C6: خالد | D6: =INDEX(الإعدادات!$D$4:$D$9,MATCH(C6,الإعدادات!$C$4:$C$9,0)) -> 2800 | E6: =INDEX(الإعدادات!$E$4:$E$9,MATCH(C6,الإعدادات!$C$4:$C$9,0)) -> 300 | F6: 12808 | G6: =MAX(0,F6-الإعدادات!$N$5)*الإعدادات!$N$6 -> 2942.4 | H6: =IF(F6>=الإعدادات!$N$7,الإعدادات!$N$8,0) -> 300 | I6: 4 | J6: =I6*الإعدادات!$N$9 -> 80 | L6: =D6+E6+G6+H6+J6+K6 -> 6422.4 | M6: 1 | N6: =M6*D6/الإعدادات!$N$10 -> 93.333333 | O6: =SUMIFS(اليومية!$F$5:$F$96,اليومية!$D$5:$D$96,"سلفة",اليومية!$E$5:$E$96,$C6,اليومية!$C$5:$C$96,$B6)+SUMIFS(اليومية!$I$5:$I$96,اليومية!$G$5:$G$96,"سلفة",اليومية!$H$5:$H$96,$C6,اليومية!$C$5:$C$96,$B6)+SUMIFS(اليومية!$L$5:$L$96,اليومية!$J$5:$J$96,"سلفة",اليومية!$K$5:$K$96,$C6,اليومية!$C$5:$C$96,$B6)+SUMIFS(اليومية!$O$5:$O$96,اليومية!$M$5:$M$96,"سلفة",اليومية!$N$5:$N$96,$C6,اليومية!$C$5:$C$96,$B6) -> 0 | P6: =N6+O6 -> 93.333333 | Q6: =L6-P6 -> 6329.0667
A7: 2026 | B7: يوليو 2026 | C7: يوسف | D7: =INDEX(الإعدادات!$D$4:$D$9,MATCH(C7,الإعدادات!$C$4:$C$9,0)) -> 2800 | E7: =INDEX(الإعدادات!$E$4:$E$9,MATCH(C7,الإعدادات!$C$4:$C$9,0)) -> 300 | F7: 14505 | G7: =MAX(0,F7-الإعدادات!$N$5)*الإعدادات!$N$6 -> 3451.5 | H7: =IF(F7>=الإعدادات!$N$7,الإعدادات!$N$8,0) -> 300 | J7: =I7*الإعدادات!$N$9 -> 0 | K7: 150 | L7: =D7+E7+G7+H7+J7+K7 -> 7001.5 | N7: =M7*D7/الإعدادات!$N$10 -> 0 | O7: =SUMIFS(اليومية!$F$5:$F$96,اليومية!$D$5:$D$96,"سلفة",اليومية!$E$5:$E$96,$C7,اليومية!$C$5:$C$96,$B7)+SUMIFS(اليومية!$I$5:$I$96,اليومية!$G$5:$G$96,"سلفة",اليومية!$H$5:$H$96,$C7,اليومية!$C$5:$C$96,$B7)+SUMIFS(اليومية!$L$5:$L$96,اليومية!$J$5:$J$96,"سلفة",اليومية!$K$5:$K$96,$C7,اليومية!$C$5:$C$96,$B7)+SUMIFS(اليومية!$O$5:$O$96,اليومية!$M$5:$M$96,"سلفة",اليومية!$N$5:$N$96,$C7,اليومية!$C$5:$C$96,$B7) -> 300 | P7: =N7+O7 -> 300 | Q7: =L7-P7 -> 6701.5
A8: 2026 | B8: يوليو 2026 | C8: سامي | D8: =INDEX(الإعدادات!$D$4:$D$9,MATCH(C8,الإعدادات!$C$4:$C$9,0)) -> 2500 | E8: =INDEX(الإعدادات!$E$4:$E$9,MATCH(C8,الإعدادات!$C$4:$C$9,0)) -> 250 | F8: 14210 | G8: =MAX(0,F8-الإعدادات!$N$5)*الإعدادات!$N$6 -> 3363 | H8: =IF(F8>=الإعدادات!$N$7,الإعدادات!$N$8,0) -> 300 | I8: 10 | J8: =I8*الإعدادات!$N$9 -> 200 | K8: -100 | L8: =D8+E8+G8+H8+J8+K8 -> 6513 | N8: =M8*D8/الإعدادات!$N$10 -> 0 | O8: =SUMIFS(اليومية!$F$5:$F$96,اليومية!$D$5:$D$96,"سلفة",اليومية!$E$5:$E$96,$C8,اليومية!$C$5:$C$96,$B8)+SUMIFS(اليومية!$I$5:$I$96,اليومية!$G$5:$G$96,"سلفة",اليومية!$H$5:$H$96,$C8,اليومية!$C$5:$C$96,$B8)+SUMIFS(اليومية!$L$5:$L$96,اليومية!$J$5:$J$96,"سلفة",اليومية!$K$5:$K$96,$C8,اليومية!$C$5:$C$96,$B8)+SUMIFS(اليومية!$O$5:$O$96,اليومية!$M$5:$M$96,"سلفة",اليومية!$N$5:$N$96,$C8,اليومية!$C$5:$C$96,$B8) -> 600 | P8: =N8+O8 -> 600 | Q8: =L8-P8 -> 5913
A9: 2026 | B9: يوليو 2026 | C9: فارس | D9: =INDEX(الإعدادات!$D$4:$D$9,MATCH(C9,الإعدادات!$C$4:$C$9,0)) -> 2500 | E9: =INDEX(الإعدادات!$E$4:$E$9,MATCH(C9,الإعدادات!$C$4:$C$9,0)) -> 250 | F9: 10694 | G9: =MAX(0,F9-الإعدادات!$N$5)*الإعدادات!$N$6 -> 2308.2 | H9: =IF(F9>=الإعدادات!$N$7,الإعدادات!$N$8,0) -> 300 | J9: =I9*الإعدادات!$N$9 -> 0 | L9: =D9+E9+G9+H9+J9+K9 -> 5358.2 | N9: =M9*D9/الإعدادات!$N$10 -> 0 | O9: =SUMIFS(اليومية!$F$5:$F$96,اليومية!$D$5:$D$96,"سلفة",اليومية!$E$5:$E$96,$C9,اليومية!$C$5:$C$96,$B9)+SUMIFS(اليومية!$I$5:$I$96,اليومية!$G$5:$G$96,"سلفة",اليومية!$H$5:$H$96,$C9,اليومية!$C$5:$C$96,$B9)+SUMIFS(اليومية!$L$5:$L$96,اليومية!$J$5:$J$96,"سلفة",اليومية!$K$5:$K$96,$C9,اليومية!$C$5:$C$96,$B9)+SUMIFS(اليومية!$O$5:$O$96,اليومية!$M$5:$M$96,"سلفة",اليومية!$N$5:$N$96,$C9,اليومية!$C$5:$C$96,$B9) -> 550 | P9: =N9+O9 -> 550 | Q9: =L9-P9 -> 4808.2
A10: 2026 | B10: يوليو 2026 | C10: ماجد | D10: =INDEX(الإعدادات!$D$4:$D$9,MATCH(C10,الإعدادات!$C$4:$C$9,0)) -> 2200 | E10: =INDEX(الإعدادات!$E$4:$E$9,MATCH(C10,الإعدادات!$C$4:$C$9,0)) -> 200 | F10: 14252 | G10: =MAX(0,F10-الإعدادات!$N$5)*الإعدادات!$N$6 -> 3375.6 | H10: =IF(F10>=الإعدادات!$N$7,الإعدادات!$N$8,0) -> 300 | I10: 4 | J10: =I10*الإعدادات!$N$9 -> 80 | L10: =D10+E10+G10+H10+J10+K10 -> 6155.6 | M10: 2 | N10: =M10*D10/الإعدادات!$N$10 -> 146.66667 | O10: =SUMIFS(اليومية!$F$5:$F$96,اليومية!$D$5:$D$96,"سلفة",اليومية!$E$5:$E$96,$C10,اليومية!$C$5:$C$96,$B10)+SUMIFS(اليومية!$I$5:$I$96,اليومية!$G$5:$G$96,"سلفة",اليومية!$H$5:$H$96,$C10,اليومية!$C$5:$C$96,$B10)+SUMIFS(اليومية!$L$5:$L$96,اليومية!$J$5:$J$96,"سلفة",اليومية!$K$5:$K$96,$C10,اليومية!$C$5:$C$96,$B10)+SUMIFS(اليومية!$O$5:$O$96,اليومية!$M$5:$M$96,"سلفة",اليومية!$N$5:$N$96,$C10,اليومية!$C$5:$C$96,$B10) -> 0 | P10: =N10+O10 -> 146.66667 | Q10: =L10-P10 -> 6008.9333
A11: 2026 | B11: أغسطس 2026 | C11: أحمد | D11: =INDEX(الإعدادات!$D$4:$D$9,MATCH(C11,الإعدادات!$C$4:$C$9,0)) -> 3000 | E11: =INDEX(الإعدادات!$E$4:$E$9,MATCH(C11,الإعدادات!$C$4:$C$9,0)) -> 300 | F11: 11191 | G11: =MAX(0,F11-الإعدادات!$N$5)*الإعدادات!$N$6 -> 2457.3 | H11: =IF(F11>=الإعدادات!$N$7,الإعدادات!$N$8,0) -> 300 | I11: 10 | J11: =I11*الإعدادات!$N$9 -> 200 | K11: -100 | L11: =D11+E11+G11+H11+J11+K11 -> 6157.3 | N11: =M11*D11/الإعدادات!$N$10 -> 0 | O11: =SUMIFS(اليومية!$F$5:$F$96,اليومية!$D$5:$D$96,"سلفة",اليومية!$E$5:$E$96,$C11,اليومية!$C$5:$C$96,$B11)+SUMIFS(اليومية!$I$5:$I$96,اليومية!$G$5:$G$96,"سلفة",اليومية!$H$5:$H$96,$C11,اليومية!$C$5:$C$96,$B11)+SUMIFS(اليومية!$L$5:$L$96,اليومية!$J$5:$J$96,"سلفة",اليومية!$K$5:$K$96,$C11,اليومية!$C$5:$C$96,$B11)+SUMIFS(اليومية!$O$5:$O$96,اليومية!$M$5:$M$96,"سلفة",اليومية!$N$5:$N$96,$C11,اليومية!$C$5:$C$96,$B11) -> 300 | P11: =N11+O11 -> 300 | Q11: =L11-P11 -> 5857.3
A12: 2026 | B12: أغسطس 2026 | C12: خالد | D12: =INDEX(الإعدادات!$D$4:$D$9,MATCH(C12,الإعدادات!$C$4:$C$9,0)) -> 2800 | E12: =INDEX(الإعدادات!$E$4:$E$9,MATCH(C12,الإعدادات!$C$4:$C$9,0)) -> 300 | F12: 16758 | G12: =MAX(0,F12-الإعدادات!$N$5)*الإعدادات!$N$6 -> 4127.4 | H12: =IF(F12>=الإعدادات!$N$7,الإعدادات!$N$8,0) -> 300 | I12: 8 | J12: =I12*الإعدادات!$N$9 -> 160 | L12: =D12+E12+G12+H12+J12+K12 -> 7687.4 | N12: =M12*D12/الإعدادات!$N$10 -> 0 | O12: =SUMIFS(اليومية!$F$5:$F$96,اليومية!$D$5:$D$96,"سلفة",اليومية!$E$5:$E$96,$C12,اليومية!$C$5:$C$96,$B12)+SUMIFS(اليومية!$I$5:$I$96,اليومية!$G$5:$G$96,"سلفة",اليومية!$H$5:$H$96,$C12,اليومية!$C$5:$C$96,$B12)+SUMIFS(اليومية!$L$5:$L$96,اليومية!$J$5:$J$96,"سلفة",اليومية!$K$5:$K$96,$C12,اليومية!$C$5:$C$96,$B12)+SUMIFS(اليومية!$O$5:$O$96,اليومية!$M$5:$M$96,"سلفة",اليومية!$N$5:$N$96,$C12,اليومية!$C$5:$C$96,$B12) -> 800 | P12: =N12+O12 -> 800 | Q12: =L12-P12 -> 6887.4
A13: 2026 | B13: أغسطس 2026 | C13: يوسف | D13: =INDEX(الإعدادات!$D$4:$D$9,MATCH(C13,الإعدادات!$C$4:$C$9,0)) -> 2800 | E13: =INDEX(الإعدادات!$E$4:$E$9,MATCH(C13,الإعدادات!$C$4:$C$9,0)) -> 300 | F13: 13925 | G13: =MAX(0,F13-الإعدادات!$N$5)*الإعدادات!$N$6 -> 3277.5 | H13: =IF(F13>=الإعدادات!$N$7,الإعدادات!$N$8,0) -> 300 | J13: =I13*الإعدادات!$N$9 -> 0 | L13: =D13+E13+G13+H13+J13+K13 -> 6677.5 | N13: =M13*D13/الإعدادات!$N$10 -> 0 | O13: =SUMIFS(اليومية!$F$5:$F$96,اليومية!$D$5:$D$96,"سلفة",اليومية!$E$5:$E$96,$C13,اليومية!$C$5:$C$96,$B13)+SUMIFS(اليومية!$I$5:$I$96,اليومية!$G$5:$G$96,"سلفة",اليومية!$H$5:$H$96,$C13,اليومية!$C$5:$C$96,$B13)+SUMIFS(اليومية!$L$5:$L$96,اليومية!$J$5:$J$96,"سلفة",اليومية!$K$5:$K$96,$C13,اليومية!$C$5:$C$96,$B13)+SUMIFS(اليومية!$O$5:$O$96,اليومية!$M$5:$M$96,"سلفة",اليومية!$N$5:$N$96,$C13,اليومية!$C$5:$C$96,$B13) -> 300 | P13: =N13+O13 -> 300 | Q13: =L13-P13 -> 6377.5
A14: 2026 | B14: أغسطس 2026 | C14: سامي | D14: =INDEX(الإعدادات!$D$4:$D$9,MATCH(C14,الإعدادات!$C$4:$C$9,0)) -> 2500 | E14: =INDEX(الإعدادات!$E$4:$E$9,MATCH(C14,الإعدادات!$C$4:$C$9,0)) -> 250 | F14: 11431 | G14: =MAX(0,F14-الإعدادات!$N$5)*الإعدادات!$N$6 -> 2529.3 | H14: =IF(F14>=الإعدادات!$N$7,الإعدادات!$N$8,0) -> 300 | J14: =I14*الإعدادات!$N$9 -> 0 | L14: =D14+E14+G14+H14+J14+K14 -> 5579.3 | M14: 1 | N14: =M14*D14/الإعدادات!$N$10 -> 83.333333 | O14: =SUMIFS(اليومية!$F$5:$F$96,اليومية!$D$5:$D$96,"سلفة",اليومية!$E$5:$E$96,$C14,اليومية!$C$5:$C$96,$B14)+SUMIFS(اليومية!$I$5:$I$96,اليومية!$G$5:$G$96,"سلفة",اليومية!$H$5:$H$96,$C14,اليومية!$C$5:$C$96,$B14)+SUMIFS(اليومية!$L$5:$L$96,اليومية!$J$5:$J$96,"سلفة",اليومية!$K$5:$K$96,$C14,اليومية!$C$5:$C$96,$B14)+SUMIFS(اليومية!$O$5:$O$96,اليومية!$M$5:$M$96,"سلفة",اليومية!$N$5:$N$96,$C14,اليومية!$C$5:$C$96,$B14) -> 1250 | P14: =N14+O14 -> 1333.3333 | Q14: =L14-P14 -> 4245.9667
A15: 2026 | B15: أغسطس 2026 | C15: فارس | D15: =INDEX(الإعدادات!$D$4:$D$9,MATCH(C15,الإعدادات!$C$4:$C$9,0)) -> 2500 | E15: =INDEX(الإعدادات!$E$4:$E$9,MATCH(C15,الإعدادات!$C$4:$C$9,0)) -> 250 | F15: 12030 | G15: =MAX(0,F15-الإعدادات!$N$5)*الإعدادات!$N$6 -> 2709 | H15: =IF(F15>=الإعدادات!$N$7,الإعدادات!$N$8,0) -> 300 | I15: 10 | J15: =I15*الإعدادات!$N$9 -> 200 | K15: -100 | L15: =D15+E15+G15+H15+J15+K15 -> 5859 | M15: 1 | N15: =M15*D15/الإعدادات!$N$10 -> 83.333333 | O15: =SUMIFS(اليومية!$F$5:$F$96,اليومية!$D$5:$D$96,"سلفة",اليومية!$E$5:$E$96,$C15,اليومية!$C$5:$C$96,$B15)+SUMIFS(اليومية!$I$5:$I$96,اليومية!$G$5:$G$96,"سلفة",اليومية!$H$5:$H$96,$C15,اليومية!$C$5:$C$96,$B15)+SUMIFS(اليومية!$L$5:$L$96,اليومية!$J$5:$J$96,"سلفة",اليومية!$K$5:$K$96,$C15,اليومية!$C$5:$C$96,$B15)+SUMIFS(اليومية!$O$5:$O$96,اليومية!$M$5:$M$96,"سلفة",اليومية!$N$5:$N$96,$C15,اليومية!$C$5:$C$96,$B15) -> 200 | P15: =N15+O15 -> 283.33333 | Q15: =L15-P15 -> 5575.6667
A16: 2026 | B16: أغسطس 2026 | C16: ماجد | D16: =INDEX(الإعدادات!$D$4:$D$9,MATCH(C16,الإعدادات!$C$4:$C$9,0)) -> 2200 | E16: =INDEX(الإعدادات!$E$4:$E$9,MATCH(C16,الإعدادات!$C$4:$C$9,0)) -> 200 | F16: 15785 | G16: =MAX(0,F16-الإعدادات!$N$5)*الإعدادات!$N$6 -> 3835.5 | H16: =IF(F16>=الإعدادات!$N$7,الإعدادات!$N$8,0) -> 300 | I16: 8 | J16: =I16*الإعدادات!$N$9 -> 160 | L16: =D16+E16+G16+H16+J16+K16 -> 6695.5 | N16: =M16*D16/الإعدادات!$N$10 -> 0 | O16: =SUMIFS(اليومية!$F$5:$F$96,اليومية!$D$5:$D$96,"سلفة",اليومية!$E$5:$E$96,$C16,اليومية!$C$5:$C$96,$B16)+SUMIFS(اليومية!$I$5:$I$96,اليومية!$G$5:$G$96,"سلفة",اليومية!$H$5:$H$96,$C16,اليومية!$C$5:$C$96,$B16)+SUMIFS(اليومية!$L$5:$L$96,اليومية!$J$5:$J$96,"سلفة",اليومية!$K$5:$K$96,$C16,اليومية!$C$5:$C$96,$B16)+SUMIFS(اليومية!$O$5:$O$96,اليومية!$M$5:$M$96,"سلفة",اليومية!$N$5:$N$96,$C16,اليومية!$C$5:$C$96,$B16) -> 300 | P16: =N16+O16 -> 300 | Q16: =L16-P16 -> 6395.5
A17: 2026 | B17: سبتمبر 2026 | C17: أحمد | D17: =INDEX(الإعدادات!$D$4:$D$9,MATCH(C17,الإعدادات!$C$4:$C$9,0)) -> 3000 | E17: =INDEX(الإعدادات!$E$4:$E$9,MATCH(C17,الإعدادات!$C$4:$C$9,0)) -> 300 | F17: 15341 | G17: =MAX(0,F17-الإعدادات!$N$5)*الإعدادات!$N$6 -> 3702.3 | H17: =IF(F17>=الإعدادات!$N$7,الإعدادات!$N$8,0) -> 300 | I17: 8 | J17: =I17*الإعدادات!$N$9 -> 160 | L17: =D17+E17+G17+H17+J17+K17 -> 7462.3 | N17: =M17*D17/الإعدادات!$N$10 -> 0 | O17: =SUMIFS(اليومية!$F$5:$F$96,اليومية!$D$5:$D$96,"سلفة",اليومية!$E$5:$E$96,$C17,اليومية!$C$5:$C$96,$B17)+SUMIFS(اليومية!$I$5:$I$96,اليومية!$G$5:$G$96,"سلفة",اليومية!$H$5:$H$96,$C17,اليومية!$C$5:$C$96,$B17)+SUMIFS(اليومية!$L$5:$L$96,اليومية!$J$5:$J$96,"سلفة",اليومية!$K$5:$K$96,$C17,اليومية!$C$5:$C$96,$B17)+SUMIFS(اليومية!$O$5:$O$96,اليومية!$M$5:$M$96,"سلفة",اليومية!$N$5:$N$96,$C17,اليومية!$C$5:$C$96,$B17) -> 150 | P17: =N17+O17 -> 150 | Q17: =L17-P17 -> 7312.3
A18: 2026 | B18: سبتمبر 2026 | C18: خالد | D18: =INDEX(الإعدادات!$D$4:$D$9,MATCH(C18,الإعدادات!$C$4:$C$9,0)) -> 2800 | E18: =INDEX(الإعدادات!$E$4:$E$9,MATCH(C18,الإعدادات!$C$4:$C$9,0)) -> 300 | F18: 10812 | G18: =MAX(0,F18-الإعدادات!$N$5)*الإعدادات!$N$6 -> 2343.6 | H18: =IF(F18>=الإعدادات!$N$7,الإعدادات!$N$8,0) -> 300 | I18: 4 | J18: =I18*الإعدادات!$N$9 -> 80 | L18: =D18+E18+G18+H18+J18+K18 -> 5823.6 | M18: 1 | N18: =M18*D18/الإعدادات!$N$10 -> 93.333333 | O18: =SUMIFS(اليومية!$F$5:$F$96,اليومية!$D$5:$D$96,"سلفة",اليومية!$E$5:$E$96,$C18,اليومية!$C$5:$C$96,$B18)+SUMIFS(اليومية!$I$5:$I$96,اليومية!$G$5:$G$96,"سلفة",اليومية!$H$5:$H$96,$C18,اليومية!$C$5:$C$96,$B18)+SUMIFS(اليومية!$L$5:$L$96,اليومية!$J$5:$J$96,"سلفة",اليومية!$K$5:$K$96,$C18,اليومية!$C$5:$C$96,$B18)+SUMIFS(اليومية!$O$5:$O$96,اليومية!$M$5:$M$96,"سلفة",اليومية!$N$5:$N$96,$C18,اليومية!$C$5:$C$96,$B18) -> 0 | P18: =N18+O18 -> 93.333333 | Q18: =L18-P18 -> 5730.2667
A19: 2026 | B19: سبتمبر 2026 | C19: يوسف | D19: =INDEX(الإعدادات!$D$4:$D$9,MATCH(C19,الإعدادات!$C$4:$C$9,0)) -> 2800 | E19: =INDEX(الإعدادات!$E$4:$E$9,MATCH(C19,الإعدادات!$C$4:$C$9,0)) -> 300 | F19: 12850 | G19: =MAX(0,F19-الإعدادات!$N$5)*الإعدادات!$N$6 -> 2955 | H19: =IF(F19>=الإعدادات!$N$7,الإعدادات!$N$8,0) -> 300 | I19: 10 | J19: =I19*الإعدادات!$N$9 -> 200 | L19: =D19+E19+G19+H19+J19+K19 -> 6555 | M19: 2 | N19: =M19*D19/الإعدادات!$N$10 -> 186.66667 | O19: =SUMIFS(اليومية!$F$5:$F$96,اليومية!$D$5:$D$96,"سلفة",اليومية!$E$5:$E$96,$C19,اليومية!$C$5:$C$96,$B19)+SUMIFS(اليومية!$I$5:$I$96,اليومية!$G$5:$G$96,"سلفة",اليومية!$H$5:$H$96,$C19,اليومية!$C$5:$C$96,$B19)+SUMIFS(اليومية!$L$5:$L$96,اليومية!$J$5:$J$96,"سلفة",اليومية!$K$5:$K$96,$C19,اليومية!$C$5:$C$96,$B19)+SUMIFS(اليومية!$O$5:$O$96,اليومية!$M$5:$M$96,"سلفة",اليومية!$N$5:$N$96,$C19,اليومية!$C$5:$C$96,$B19) -> 0 | P19: =N19+O19 -> 186.66667 | Q19: =L19-P19 -> 6368.3333
A20: 2026 | B20: سبتمبر 2026 | C20: سامي | D20: =INDEX(الإعدادات!$D$4:$D$9,MATCH(C20,الإعدادات!$C$4:$C$9,0)) -> 2500 | E20: =INDEX(الإعدادات!$E$4:$E$9,MATCH(C20,الإعدادات!$C$4:$C$9,0)) -> 250 | F20: 13961 | G20: =MAX(0,F20-الإعدادات!$N$5)*الإعدادات!$N$6 -> 3288.3 | H20: =IF(F20>=الإعدادات!$N$7,الإعدادات!$N$8,0) -> 300 | I20: 8 | J20: =I20*الإعدادات!$N$9 -> 160 | K20: -100 | L20: =D20+E20+G20+H20+J20+K20 -> 6398.3 | N20: =M20*D20/الإعدادات!$N$10 -> 0 | O20: =SUMIFS(اليومية!$F$5:$F$96,اليومية!$D$5:$D$96,"سلفة",اليومية!$E$5:$E$96,$C20,اليومية!$C$5:$C$96,$B20)+SUMIFS(اليومية!$I$5:$I$96,اليومية!$G$5:$G$96,"سلفة",اليومية!$H$5:$H$96,$C20,اليومية!$C$5:$C$96,$B20)+SUMIFS(اليومية!$L$5:$L$96,اليومية!$J$5:$J$96,"سلفة",اليومية!$K$5:$K$96,$C20,اليومية!$C$5:$C$96,$B20)+SUMIFS(اليومية!$O$5:$O$96,اليومية!$M$5:$M$96,"سلفة",اليومية!$N$5:$N$96,$C20,اليومية!$C$5:$C$96,$B20) -> 100 | P20: =N20+O20 -> 100 | Q20: =L20-P20 -> 6298.3
A21: 2026 | B21: سبتمبر 2026 | C21: فارس | D21: =INDEX(الإعدادات!$D$4:$D$9,MATCH(C21,الإعدادات!$C$4:$C$9,0)) -> 2500 | E21: =INDEX(الإعدادات!$E$4:$E$9,MATCH(C21,الإعدادات!$C$4:$C$9,0)) -> 250 | F21: 16715 | G21: =MAX(0,F21-الإعدادات!$N$5)*الإعدادات!$N$6 -> 4114.5 | H21: =IF(F21>=الإعدادات!$N$7,الإعدادات!$N$8,0) -> 300 | J21: =I21*الإعدادات!$N$9 -> 0 | L21: =D21+E21+G21+H21+J21+K21 -> 7164.5 | M21: 1 | N21: =M21*D21/الإعدادات!$N$10 -> 83.333333 | O21: =SUMIFS(اليومية!$F$5:$F$96,اليومية!$D$5:$D$96,"سلفة",اليومية!$E$5:$E$96,$C21,اليومية!$C$5:$C$96,$B21)+SUMIFS(اليومية!$I$5:$I$96,اليومية!$G$5:$G$96,"سلفة",اليومية!$H$5:$H$96,$C21,اليومية!$C$5:$C$96,$B21)+SUMIFS(اليومية!$L$5:$L$96,اليومية!$J$5:$J$96,"سلفة",اليومية!$K$5:$K$96,$C21,اليومية!$C$5:$C$96,$B21)+SUMIFS(اليومية!$O$5:$O$96,اليومية!$M$5:$M$96,"سلفة",اليومية!$N$5:$N$96,$C21,اليومية!$C$5:$C$96,$B21) -> 750 | P21: =N21+O21 -> 833.33333 | Q21: =L21-P21 -> 6331.1667
A22: 2026 | B22: سبتمبر 2026 | C22: ماجد | D22: =INDEX(الإعدادات!$D$4:$D$9,MATCH(C22,الإعدادات!$C$4:$C$9,0)) -> 2200 | E22: =INDEX(الإعدادات!$E$4:$E$9,MATCH(C22,الإعدادات!$C$4:$C$9,0)) -> 200 | F22: 14486 | G22: =MAX(0,F22-الإعدادات!$N$5)*الإعدادات!$N$6 -> 3445.8 | H22: =IF(F22>=الإعدادات!$N$7,الإعدادات!$N$8,0) -> 300 | I22: 8 | J22: =I22*الإعدادات!$N$9 -> 160 | K22: 150 | L22: =D22+E22+G22+H22+J22+K22 -> 6455.8 | N22: =M22*D22/الإعدادات!$N$10 -> 0 | O22: =SUMIFS(اليومية!$F$5:$F$96,اليومية!$D$5:$D$96,"سلفة",اليومية!$E$5:$E$96,$C22,اليومية!$C$5:$C$96,$B22)+SUMIFS(اليومية!$I$5:$I$96,اليومية!$G$5:$G$96,"سلفة",اليومية!$H$5:$H$96,$C22,اليومية!$C$5:$C$96,$B22)+SUMIFS(اليومية!$L$5:$L$96,اليومية!$J$5:$J$96,"سلفة",اليومية!$K$5:$K$96,$C22,اليومية!$C$5:$C$96,$B22)+SUMIFS(اليومية!$O$5:$O$96,اليومية!$M$5:$M$96,"سلفة",اليومية!$N$5:$N$96,$C22,اليومية!$C$5:$C$96,$B22) -> 850 | P22: =N22+O22 -> 850 | Q22: =L22-P22 -> 5605.8
A23: الإجمالي | D23: =SUM(D5:D22) -> 47400 | E23: =SUM(E5:E22) -> 4800 | F23: =SUM(F5:F22) -> 242133 | G23: =SUM(G5:G22) -> 56439.9 | H23: =SUM(H5:H22) -> 5400 | I23: =SUM(I5:I22) -> 100 | J23: =SUM(J5:J22) -> 2000 | K23: =SUM(K5:K22) -> -100 | ... Q23: =SUM(Q5:Q22) -> 108169.9

Sheet الدفتر
A1: الدفتر — كل الحركات بدليل حسابات مكوّد
A2: الصفوف الملوّنة قيود آلية من اليومية والرواتب — الكود والتصنيف والضريبة محسوبين لكل سطر
A4: التاريخ | B4: البيان | C4: الحساب | D4: المورد / الجهة | E4: الرقم الضريبي | F4: وارد | G4: منصرف | H4: الحساب النقدي | I4: خاضع؟ | J4: ربع الإقرار | K4: المصدر | L4: الكود | M4: التصنيف العام | N4: الطبيعة | O4: القائمة | P4: الشهر | Q4: الربع | R4: ضريبة المخرجات | S4: ضريبة المدخلات | T4: الصافي قبل الضريبة
A5: 46204 | B5: إيجار الشهر — قسط من الدفعة النصف سنوية | C5: الإيجار | D5: شركة الأفق العقارية | E5: 300112233400003 | G5: 11500 | H5: البنك | I5: 1 | K5: استحقاق شهري | L5: =IFERROR(INDEX(الإعدادات!$G$4:$G$15,MATCH($C5,الإعدادات!$H$4:$H$15,0)),"غير معرف") -> 5200 | M5: =IFERROR(INDEX(الإعدادات!$I$4:$I$15,MATCH($C5,الإعدادات!$H$4:$H$15,0)),"غير معرف") -> مصاريف الفرع | N5: =IFERROR(INDEX(الإعدادات!$J$4:$J$15,MATCH($C5,الإعدادات!$H$4:$H$15,0)),"غير معرف") -> مصروف | O5: =IFERROR(INDEX(الإعدادات!$K$4:$K$15,MATCH($C5,الإعدادات!$H$4:$H$15,0)),"غير معرف") -> قائمة الدخل | P5: =MONTH(A5) -> 7 | Q5: =YEAR(A5)&"-Q"&ROUNDUP(MONTH(A5)/3,0) -> 2026-Q3 | R5: =IF(AND(I5=1,F5>0),F5*الإعدادات!$N$4/(1+الإعدادات!$N$4),0) -> 0 | S5: =IF(AND(I5=1,G5>0),G5*الإعدادات!$N$4/(1+الإعدادات!$N$4),0) -> 1500 | T5: =F5+G5-R5-S5 -> 10000
A6: 46208 | B6: فاتورة كهرباء ومياه | C6: الكهرباء والمياه | D6: شركة الكهرباء | E6: 300000000100003 | G6: 1541 | H6: البنك | I6: 1 | K6: إدخال يدوي | L6: =IFERROR(INDEX(الإعدادات!$G$4:$G$15,MATCH($C6,الإعدادات!$H$4:$H$15,0)),"غير معرف") -> 5210 | M6: =IFERROR(INDEX(الإعدادات!$I$4:$I$15,MATCH($C6,الإعدادات!$H$4:$H$15,0)),"غير معرف") -> مصاريف الفرع | N6: =IFERROR(INDEX(الإعدادات!$J$4:$J$15,MATCH($C6,الإعدادات!$H$4:$H$15,0)),"غير معرف") -> مصروف | O6: =IFERROR(INDEX(الإعدادات!$K$4:$K$15,MATCH($C6,الإعدادات!$H$4:$H$15,0)),"غير معرف") -> قائمة الدخل | P6: =MONTH(A6) -> 7 | Q6: =YEAR(A6)&"-Q"&ROUNDUP(MONTH(A6)/3,0) -> 2026-Q3 | R6: =IF(AND(I6=1,F6>0),F6*الإعدادات!$N$4/(1+الإعدادات!$N$4),0) -> 0 | S6: =IF(AND(I6=1,G6>0),G6*الإعدادات!$N$4/(1+الإعدادات!$N$4),0) -> 201 | T6: =F6+G6-R6-S6 -> 1340
A7: 46213 | B7: شراء مستلزمات ومنتجات | C7: المستلزمات والأدوات | D7: شركة الإمداد التجارية | E7: 300554433200003 | G7: 5684 | H7: البنك | I7: 1 | K7: إدخال يدوي | L7: =IFERROR(INDEX(الإعدادات!$G$4:$G$15,MATCH($C7,الإعدادات!$H$4:$H$15,0)),"غير معرف") -> 5220 | M7: =IFERROR(INDEX(الإعدادات!$I$4:$I$15,MATCH($C7,الإعدادات!$H$4:$H$15,0)),"غير معرف") -> مصاريف التشغيل | N7: =IFERROR(INDEX(الإعدادات!$J$4:$J$15,MATCH($C7,الإعدادات!$H$4:$H$15,0)),"غير معرف") -> مصروف | O7: =IFERROR(INDEX(الإعدادات!$K$4:$K$15,MATCH($C7,الإعدادات!$H$4:$H$15,0)),"غير معرف") -> قائمة الدخل | P7: =MONTH(A7) -> 7 | Q7: =YEAR(A7)&"-Q"&ROUNDUP(MONTH(A7)/3,0) -> 2026-Q3 | R7: =IF(AND(I7=1,F7>0),F7*الإعدادات!$N$4/(1+الإعدادات!$N$4),0) -> 0 | S7: =IF(AND(I7=1,G7>0),G7*الإعدادات!$N$4/(1+الإعدادات!$N$4),0) -> 741.3913 | T7: =F7+G7-R7-S7 -> 4942.6087
A8: 46223 | B8: شراء مستلزمات ومنتجات | C8: المستلزمات والأدوات | D8: مؤسسة النخبة للمستلزمات | E8: 300998877600003 | G8: 4843 | H8: البنك | I8: 1 | K8: إدخال يدوي | L8: =IFERROR(INDEX(الإعدادات!$G$4:$G$15,MATCH($C8,الإعدادات!$H$4:$H$15,0)),"غير معرف") -> 5220 | M8: =IFERROR(INDEX(الإعدادات!$I$4:$I$15,MATCH($C8,الإعدادات!$H$4:$H$15,0)),"غير معرف") -> مصاريف التشغيل | N8: =IFERROR(INDEX(الإعدادات!$J$4:$J$15,MATCH($C8,الإعدادات!$H$4:$H$15,0)),"غير معرف") -> مصروف | O8: =IFERROR(INDEX(الإعدادات!$K$4:$K$15,MATCH($C8,الإعدادات!$H$4:$H$15,0)),"غير معرف") -> قائمة الدخل | P8: =MONTH(A8) -> 7 | Q8: =YEAR(A8)&"-Q"&ROUNDUP(MONTH(A8)/3,0) -> 2026-Q3 | R8: =IF(AND(I8=1,F8>0),F8*الإعدادات!$N$4/(1+الإعدادات!$N$4),0) -> 0 | S8: =IF(AND(I8=1,G8>0),G8*الإعدادات!$N$4/(1+الإعدادات!$N$4),0) -> 631.69565 | T8: =F8+G8-R8-S8 -> 4211.3043
A9: 46228 | B9: حملة إعلانية على السوشيال | C9: التسويق | D9: وكالة ومضة | E9: 300776655400003 | G9: 1757 | H9: البنك | I9: 1 | K9: إدخال يدوي | L9: =IFERROR(INDEX(الإعدادات!$G$4:$G$15,MATCH($C9,الإعدادات!$H$4:$H$15,0)),"غير معرف") -> 5300 | M9: =IFERROR(INDEX(الإعدادات!$I$4:$I$15,MATCH($C9,الإعدادات!$H$4:$H$15,0)),"غير معرف") -> مصاريف التشغيل | N9: =IFERROR(INDEX(الإعدادات!$J$4:$J$15,MATCH($C9,الإعدادات!$H$4:$H$15,0)),"غير معرف") -> مصروف | O9: =IFERROR(INDEX(الإعدادات!$K$4:$K$15,MATCH($C9,الإعدادات!$H$4:$H$15,0)),"غير معرف") -> قائمة الدخل | P9: =MONTH(A9) -> 7 | Q9: =YEAR(A9)&"-Q"&ROUNDUP(MONTH(A9)/3,0) -> 2026-Q3 | R9: =IF(AND(I9=1,F9>0),F9*الإعدادات!$N$4/(1+الإعدادات!$N$4),0) -> 0 | S9: =IF(AND(I9=1,G9>0),G9*الإعدادات!$N$4/(1+الإعدادات!$N$4),0) -> 229.17391 | T9: =F9+G9-R9-S9 -> 1527.8261
A10: 46231 | B10: عمولة بوابات الدفع | C10: رسوم بوابات الدفع | D10: بنك محلي | G10: 865 | H10: البنك | I10: 1 | K10: إدخال يدوي | L10: =IFERROR(INDEX(الإعدادات!$G$4:$G$15,MATCH($C10,الإعدادات!$H$4:$H$15,0)),"غير معرف") -> 5400 | M10: =IFERROR(INDEX(الإعدادات!$I$4:$I$15,MATCH($C10,الإعدادات!$H$4:$H$15,0)),"غير معرف") -> مصاريف التشغيل | N10: =IFERROR(INDEX(الإعدادات!$J$4:$J$15,MATCH($C10,الإعدادات!$H$4:$H$15,0)),"غير معرف") -> مصروف | O10: =IFERROR(INDEX(الإعدادات!$K$4:$K$15,MATCH($C10,الإعدادات!$H$4:$H$15,0)),"غير معرف") -> قائمة الدخل | P10: =MONTH(A10) -> 7 | Q10: =YEAR(A10)&"-Q"&ROUNDUP(MONTH(A10)/3,0) -> 2026-Q3 | R10: =IF(AND(I10=1,F10>0),F10*الإعدادات!$N$4/(1+الإعدادات!$N$4),0) -> 0 | S10: =IF(AND(I10=1,G10>0),G10*الإعدادات!$N$4/(1+الإعدادات!$N$4),0) -> 112.82609 | T10: =F10+G10-R10-S10 -> 752.17391
A11: 46234 | B11: إيرادات يوليو 2026 — من اليومية | C11: مبيعات الخدمات | F11: =SUMIFS(اليومية!$V$5:$V$96,اليومية!$C$5:$C$96,"يوليو 2026") -> 125981 | H11: البنك | I11: 1 | K11: قيد آلي — اليومية | L11: =IFERROR(INDEX(الإعدادات!$G$4:$G$15,MATCH($C11,الإعدادات!$H$4:$H$15,0)),"غير معرف") -> 4100 | M11: =IFERROR(INDEX(الإعدادات!$I$4:$I$15,MATCH($C11,الإعدادات!$H$4:$H$15,0)),"غير معرف") -> الإيرادات | N11: =IFERROR(INDEX(الإعدادات!$J$4:$J$15,MATCH($C11,الإعدادات!$H$4:$H$15,0)),"غير معرف") -> إيراد | O11: =IFERROR(INDEX(الإعدادات!$K$4:$K$15,MATCH($C11,الإعدادات!$H$4:$H$15,0)),"غير معرف") -> قائمة الدخل | P11: =MONTH(A11) -> 7 | Q11: =YEAR(A11)&"-Q"&ROUNDUP(MONTH(A11)/3,0) -> 2026-Q3 | R11: =IF(AND(I11=1,F11>0),F11*الإعدادات!$N$4/(1+الإعدادات!$N$4),0) -> 16432.304 | S11: =IF(AND(I11=1,G11>0),G11*الإعدادات!$N$4/(1+الإعدادات!$N$4),0) -> 0 | T11: =F11+G11-R11-S11 -> 109548.7
A12: 46234 | B12: نثريات الدرج يوليو 2026 (بدون السلف) | C12: مصروفات نثرية من الدرج | G12: =SUMIFS(اليومية!$P$5:$P$96,اليومية!$C$5:$C$96,"يوليو 2026")-SUMIFS(الرواتب!$O$5:$O$22,الرواتب!$B$5:$B$22,"يوليو 2026") -> 3363 | H12: الكاش | I12: 0 | K12: قيد آلي — اليومية | L12: =IFERROR(INDEX(الإعدادات!$G$4:$G$15,MATCH($C12,الإعدادات!$H$4:$H$15,0)),"غير معرف") -> 5900 | M12: =IFERROR(INDEX(الإعدادات!$I$4:$I$15,MATCH($C12,الإعدادات!$H$4:$H$15,0)),"غير معرف") -> مصاريف التشغيل | N12: =IFERROR(INDEX(الإعدادات!$J$4:$J$15,MATCH($C12,الإعدادات!$H$4:$H$15,0)),"غير معرف") -> مصروف | O12: =IFERROR(INDEX(الإعدادات!$K$4:$K$15,MATCH($C12,الإعدادات!$H$4:$H$15,0)),"غير معرف") -> قائمة الدخل | P12: =MONTH(A12) -> 7 | Q12: =YEAR(A12)&"-Q"&ROUNDUP(MONTH(A12)/3,0) -> 2026-Q3 | R12: =IF(AND(I12=1,F12>0),F12*الإعدادات!$N$4/(1+الإعدادات!$N$4),0) -> 0 | S12: =IF(AND(I12=1,G12>0),G12*الإعدادات!$N$4/(1+الإعدادات!$N$4),0) -> 0 | T12: =F12+G12-R12-S12 -> 3363
A13: 46234 | B13: رواتب وبدلات يوليو 2026 | C13: الرواتب والبدلات | G13: =SUMIFS(الرواتب!$D$5:$D$22,الرواتب!$B$5:$B$22,"يوليو 2026")+SUMIFS(الرواتب!$E$5:$E$22,الرواتب!$B$5:$B$22,"يوليو 2026")-SUMIFS(الرواتب!$N$5:$N$22,الرواتب!$B$5:$B$22,"يوليو 2026") -> 17160 | H13: البنك | I13: 0 | K13: قيد آلي — الرواتب | L13: =IFERROR(INDEX(الإعدادات!$G$4:$G$15,MATCH($C13,الإعدادات!$H$4:$H$15,0)),"غير معرف") -> 5100 | M13: =IFERROR(INDEX(الإعدادات!$I$4:$I$15,MATCH($C13,الإعدادات!$H$4:$H$15,0)),"غير معرف") -> مصاريف الموظفين | N13: =IFERROR(INDEX(الإعدادات!$J$4:$J$15,MATCH($C13,الإعدادات!$H$4:$H$15,0)),"غير معرف") -> مصروف | O13: =IFERROR(INDEX(الإعدادات!$K$4:$K$15,MATCH($C13,الإعدادات!$H$4:$H$15,0)),"غير معرف") -> قائمة الدخل | P13: =MONTH(A13) -> 7 | Q13: =YEAR(A13)&"-Q"&ROUNDUP(MONTH(A13)/3,0) -> 2026-Q3 | R13: =IF(AND(I13=1,F13>0),F13*الإعدادات!$N$4/(1+الإعدادات!$N$4),0) -> 0 | S13: =IF(AND(I13=1,G13>0),G13*الإعدادات!$N$4/(1+الإعدادات!$N$4),0) -> 0 | T13: =F13+G13-R13-S13 -> 17160
A14: 46234 | B14: عمولات وحوافز يوليو 2026 | C14: العمولات والحوافز | G14: =SUMIFS(الرواتب!$G$5:$G$22,الرواتب!$B$5:$B$22,"يوليو 2026")+SUMIFS(الرواتب!$H$5:$H$22,الرواتب!$B$5:$B$22,"يوليو 2026")+SUMIFS(الرواتب!$J$5:$J$22,الرواتب!$B$5:$B$22,"يوليو 2026")+SUMIFS(الرواتب!$K$5:$K$22,الرواتب!$B$5:$B$22,"يوليو 2026") -> 20024.4 | H14: البنك | I14: 0 | K14: قيد آلي — الرواتب | L14: =IFERROR(INDEX(الإعدادات!$G$4:$G$15,MATCH($C14,الإعدادات!$H$4:$H$15,0)),"غير معرف") -> 5110 | M14: =IFERROR(INDEX(الإعدادات!$I$4:$I$15,MATCH($C14,الإعدادات!$H$4:$H$15,0)),"غير معرف") -> مصاريف الموظفين | N14: =IFERROR(INDEX(الإعدادات!$J$4:$J$15,MATCH($C14,الإعدادات!$H$4:$H$15,0)),"غير معرف") -> مصروف | O14: =IFERROR(INDEX(الإعدادات!$K$4:$K$15,MATCH($C14,الإعدادات!$H$4:$H$15,0)),"غير معرف") -> قائمة الدخل | P14: =MONTH(A14) -> 7 | Q14: =YEAR(A14)&"-Q"&ROUNDUP(MONTH(A14)/3,0) -> 2026-Q3 | R14: =IF(AND(I14=1,F14>0),F14*الإعدادات!$N$4/(1+الإعدادات!$N$4),0) -> 0 | S14: =IF(AND(I14=1,G14>0),G14*الإعدادات!$N$4/(1+الإعدادات!$N$4),0) -> 0 | T14: =F14+G14-R14-S14 -> 20024.4
A15: 46235 | B15: إيجار الشهر — قسط من الدفعة النصف سنوية | C15: الإيجار | D15: شركة الأفق العقارية | E15: 300112233400003 | G15: 11500 | H15: البنك | I15: 1 | K15: استحقاق شهري | L15: =IFERROR(INDEX(الإعدادات!$G$4:$G$15,MATCH($C15,الإعدادات!$H$4:$H$15,0)),"غير معرف") -> 5200 | M15: =IFERROR(INDEX(الإعدادات!$I$4:$I$15,MATCH($C15,الإعدادات!$H$4:$H$15,0)),"غير معرف") -> مصاريف الفرع | N15: =IFERROR(INDEX(الإعدادات!$J$4:$J$15,MATCH($C15,الإعدادات!$H$4:$H$15,0)),"غير معرف") -> مصروف | O15: =IFERROR(INDEX(الإعدادات!$K$4:$K$15,MATCH($C15,الإعدادات!$H$4:$H$15,0)),"غير معرف") -> قائمة الدخل | P15: =MONTH(A15) -> 8 | Q15: =YEAR(A15)&"-Q"&ROUNDUP(MONTH(A15)/3,0) -> 2026-Q3 | R15: =IF(AND(I15=1,F15>0),F15*الإعدادات!$N$4/(1+الإعدادات!$N$4),0) -> 0 | S15: =IF(AND(I15=1,G15>0),G15*الإعدادات!$N$4/(1+الإعدادات!$N$4),0) -> 1500 | T15: =F15+G15-R15-S15 -> 10000
A16: 46239 | B16: فاتورة كهرباء ومياه | C16: الكهرباء والمياه | D16: شركة الكهرباء | E16: 300000000100003 | G16: 1845 | H16: البنك | I16: 1 | K16: إدخال يدوي | L16: =IFERROR(INDEX(الإعدادات!$G$4:$G$15,MATCH($C16,الإعدادات!$H$4:$H$15,0)),"غير معرف") -> 5210 | M16: =IFERROR(INDEX(الإعدادات!$I$4:$I$15,MATCH($C16,الإعدادات!$H$4:$H$15,0)),"غير معرف") -> مصاريف الفرع | N16: =IFERROR(INDEX(الإعدادات!$J$4:$J$15,MATCH($C16,الإعدادات!$H$4:$H$15,0)),"غير معرف") -> مصروف | O16: =IFERROR(INDEX(الإعدادات!$K$4:$K$15,MATCH($C16,الإعدادات!$H$4:$H$15,0)),"غير معرف") -> قائمة الدخل | P16: =MONTH(A16) -> 8 | Q16: =YEAR(A16)&"-Q"&ROUNDUP(MONTH(A16)/3,0) -> 2026-Q3 | R16: =IF(AND(I16=1,F16>0),F16*الإعدادات!$N$4/(1+الإعدادات!$N$4),0) -> 0 | S16: =IF(AND(I16=1,G16>0),G16*الإعدادات!$N$4/(1+الإعدادات!$N$4),0) -> 240.65217 | T16: =F16+G16-R16-S16 -> 1604.3478
A17: 46243 | B17: شراء مستلزمات ومنتجات | C17: المستلزمات والأدوات | D17: مؤسسة النخبة للمستلزمات | E17: 300998877600003 | G17: 5633 | H17: البنك | I17: 1 | K17: إدخال يدوي | L17: =IFERROR(INDEX(الإعدادات!$G$4:$G$15,MATCH($C17,الإعدادات!$H$4:$H$15,0)),"غير معرف") -> 5220 | M17: =IFERROR(INDEX(الإعدادات!$I$4:$I$15,MATCH($C17,الإعدادات!$H$4:$H$15,0)),"غير معرف") -> مصاريف التشغيل | N17: =IFERROR(INDEX(الإعدادات!$J$4:$J$15,MATCH($C17,الإعدادات!$H$4:$H$15,0)),"غير معرف") -> مصروف | O17: =IFERROR(INDEX(الإعدادات!$K$4:$K$15,MATCH($C17,الإعدادات!$H$4:$H$15,0)),"غير معرف") -> قائمة الدخل | P17: =MONTH(A17) -> 8 | Q17: =YEAR(A17)&"-Q"&ROUNDUP(MONTH(A17)/3,0) -> 2026-Q3 | R17: =IF(AND(I17=1,F17>0),F17*الإعدادات!$N$4/(1+الإعدادات!$N$4),0) -> 0 | S17: =IF(AND(I17=1,G17>0),G17*الإعدادات!$N$4/(1+الإعدادات!$N$4),0) -> 734.73913 | T17: =F17+G17-R17-S17 -> 4898.2609
A18: 46246 | B18: صيانة مكيفات | C18: الصيانة والإصلاحات | D18: ورشة التبريد | G18: 950 | H18: الكاش | I18: 0 | K18: إدخال يدوي | L18: =IFERROR(INDEX(الإعدادات!$G$4:$G$15,MATCH($C18,الإعدادات!$H$4:$H$15,0)),"غير معرف") -> 5230 | M18: =IFERROR(INDEX(الإعدادات!$I$4:$I$15,MATCH($C18,الإعدادات!$H$4:$H$15,0)),"غير معرف") -> مصاريف الفرع | N18: =IFERROR(INDEX(الإعدادات!$J$4:$J$15,MATCH($C18,الإعدادات!$H$4:$H$15,0)),"غير معرف") -> مصروف | O18: =IFERROR(INDEX(الإعدادات!$K$4:$K$15,MATCH($C18,الإعدادات!$H$4:$H$15,0)),"غير معرف") -> قائمة الدخل | P18: =MONTH(A18) -> 8 | Q18: =YEAR(A18)&"-Q"&ROUNDUP(MONTH(A18)/3,0) -> 2026-Q3 | R18: =IF(AND(I18=1,F18>0),F18*الإعدادات!$N$4/(1+الإعدادات!$N$4),0) -> 0 | S18: =IF(AND(I18=1,G18>0),G18*الإعدادات!$N$4/(1+الإعدادات!$N$4),0) -> 0 | T18: =F18+G18-R18-S18 -> 950
A19: 46252 | B19: تجديد تأمين طبي — موظفين | C19: تكاليف الموظفين (تأشيرات وتأمين) | D19: شركة التأمين | G19: 2880 | H19: البنك | I19: 0 | K19: إدخال يدوي | L19: =IFERROR(INDEX(الإعدادات!$G$4:$G$15,MATCH($C19,الإعدادات!$H$4:$H$15,0)),"غير معرف") -> 5120 | M19: =IFERROR(INDEX(الإعدادات!$I$4:$I$15,MATCH($C19,الإعدادات!$H$4:$H$15,0)),"غير معرف") -> مصاريف الموظفين | N19: =IFERROR(INDEX(الإعدادات!$J$4:$J$15,MATCH($C19,الإعدادات!$H$4:$H$15,0)),"غير معرف") -> مصروف | O19: =IFERROR(INDEX(الإعدادات!$K$4:$K$15,MATCH($C19,الإعدادات!$H$4:$H$15,0)),"غير معرف") -> قائمة الدخل | P19: =MONTH(A19) -> 8 | Q19: =YEAR(A19)&"-Q"&ROUNDUP(MONTH(A19)/3,0) -> 2026-Q3 | R19: =IF(AND(I19=1,F19>0),F19*الإعدادات!$N$4/(1+الإعدادات!$N$4),0) -> 0 | S19: =IF(AND(I19=1,G19>0),G19*الإعدادات!$N$4/(1+الإعدادات!$N$4),0) -> 0 | T19: =F19+G19-R19-S19 -> 2880
A20: 46254 | B20: شراء مستلزمات ومنتجات | C20: المستلزمات والأدوات | D20: شركة الإمداد التجارية | E20: 300554433200003 | G20: 5226 | H20: البنك | I20: 1 | K20: إدخال يدوي | L20: =IFERROR(INDEX(الإعدادات!$G$4:$G$15,MATCH($C20,الإعدادات!$H$4:$H$15,0)),"غير معرف") -> 5220 | M20: =IFERROR(INDEX(الإعدادات!$I$4:$I$15,MATCH($C20,الإعدادات!$H$4:$H$15,0)),"غير معرف") -> مصاريف التشغيل | N20: =IFERROR(INDEX(الإعدادات!$J$4:$J$15,MATCH($C20,الإعدادات!$H$4:$H$15,0)),"غير معرف") -> مصروف | O20: =IFERROR(INDEX(الإعدادات!$K$4:$K$15,MATCH($C20,الإعدادات!$H$4:$H$15,0)),"غير معرف") -> قائمة الدخل | P20: =MONTH(A20) -> 8 | Q20: =YEAR(A20)&"-Q"&ROUNDUP(MONTH(A20)/3,0) -> 2026-Q3 | R20: =IF(AND(I20=1,F20>0),F20*الإعدادات!$N$4/(1+الإعدادات!$N$4),0) -> 0 | S20: =IF(AND(I20=1,G20>0),G20*الإعدادات!$N$4/(1+الإعدادات!$N$4),0) -> 681.65217 | T20: =F20+G20-R20-S20 -> 4544.3478
A21: 46259 | B21: حملة إعلانية على السوشيال | C21: التسويق | D21: وكالة ومضة | E21: 300776655400003 | G21: 1639 | H21: البنك | I21: 1 | K21: إدخال يدوي | L21: =IFERROR(INDEX(الإعدادات!$G$4:$G$15,MATCH($C21,الإعدادات!$H$4:$H$15,0)),"غير معرف") -> 5300 | M21: =IFERROR(INDEX(الإعدادات!$I$4:$I$15,MATCH($C21,الإعدادات!$H$4:$H$15,0)),"غير معرف") -> مصاريف التشغيل | N21: =IFERROR(INDEX(الإعدادات!$J$4:$J$15,MATCH($C21,الإعدادات!$H$4:$H$15,0)),"غير معرف") -> مصروف | O21: =IFERROR(INDEX(الإعدادات!$K$4:$K$15,MATCH($C21,الإعدادات!$H$4:$H$15,0)),"غير معرف") -> قائمة الدخل | P21: =MONTH(A21) -> 8 | Q21: =YEAR(A21)&"-Q"&ROUNDUP(MONTH(A21)/3,0) -> 2026-Q3 | R21: =IF(AND(I21=1,F21>0),F21*الإعدادات!$N$4/(1+الإعدادات!$N$4),0) -> 0 | S21: =IF(AND(I21=1,G21>0),G21*الإعدادات!$N$4/(1+الإعدادات!$N$4),0) -> 213.78261 | T21: =F21+G21-R21-S21 -> 1425.2174
A22: 46262 | B22: عمولة بوابات الدفع | C22: رسوم بوابات الدفع | D22: بنك محلي | G22: 833 | H22: البنك | I22: 1 | K22: إدخال يدوي | L22: =IFERROR(INDEX(الإعدادات!$G$4:$G$15,MATCH($C22,الإعدادات!$H$4:$H$15,0)),"غير معرف") -> 5400 | M22: =IFERROR(INDEX(الإعدادات!$I$4:$I$15,MATCH($C22,الإعدادات!$H$4:$H$15,0)),"غير معرف") -> مصاريف التشغيل | N22: =IFERROR(INDEX(الإعدادات!$J$4:$J$15,MATCH($C22,الإعدادات!$H$4:$H$15,0)),"غير معرف") -> مصروف | O22: =IFERROR(INDEX(الإعدادات!$K$4:$K$15,MATCH($C22,الإعدادات!$H$4:$H$15,0)),"غير معرف") -> قائمة الدخل | P22: =MONTH(A22) -> 8 | Q22: =YEAR(A22)&"-Q"&ROUNDUP(MONTH(A22)/3,0) -> 2026-Q3 | R22: =IF(AND(I22=1,F22>0),F22*الإعدادات!$N$4/(1+الإعدادات!$N$4),0) -> 0 | S22: =IF(AND(I22=1,G22>0),G22*الإعدادات!$N$4/(1+الإعدادات!$N$4),0) -> 108.65217 | T22: =F22+G22-R22-S22 -> 724.34783
A23: 46265 | B23: إيرادات أغسطس 2026 — من اليومية | C23: مبيعات الخدمات | F23: =SUMIFS(اليومية!$V$5:$V$96,اليومية!$C$5:$C$96,"أغسطس 2026") -> 127398 | H23: البنك | I23: 1 | K23: قيد آلي — اليومية | L23: =IFERROR(INDEX(الإعدادات!$G$4:$G$15,MATCH($C23,الإعدادات!$H$4:$H$15,0)),"غير معرف") -> 4100 | M23: =IFERROR(INDEX(الإعدادات!$I$4:$I$15,MATCH($C23,الإعدادات!$H$4:$H$15,0)),"غير معرف") -> الإيرادات | N23: =IFERROR(INDEX(الإعدادات!$J$4:$J$15,MATCH($C23,الإعدادات!$H$4:$H$15,0)),"غير معرف") -> إيراد | O23: =IFERROR(INDEX(الإعدادات!$K$4:$K$15,MATCH($C23,الإعدادات!$H$4:$H$15,0)),"غير معرف") -> قائمة الدخل | P23: =MONTH(A23) -> 8 | Q23: =YEAR(A23)&"-Q"&ROUNDUP(MONTH(A23)/3,0) -> 2026-Q3 | R23: =IF(AND(I23=1,F23>0),F23*الإعدادات!$N$4/(1+الإعدادات!$N$4),0) -> 16617.13 | S23: =IF(AND(I23=1,G23>0),G23*الإعدادات!$N$4/(1+الإعدادات!$N$4),0) -> 0 | T23: =F23+G23-R23-S23 -> 110780.87
A24: 46265 | B24: نثريات الدرج أغسطس 2026 (بدون السلف) | C24: مصروفات نثرية من الدرج | G24: =SUMIFS(اليومية!$P$5:$P$96,اليومية!$C$5:$C$96,"أغسطس 2026")-SUMIFS(الرواتب!$O$5:$O$22,الرواتب!$B$5:$B$22,"أغسطس 2026") -> 2631 | H24: الكاش | I24: 0 | K24: قيد آلي — اليومية | L24: =IFERROR(INDEX(الإعدادات!$G$4:$G$15,MATCH($C24,الإعدادات!$H$4:$H$15,0)),"غير معرف") -> 5900 | M24: =IFERROR(INDEX(الإعدادات!$I$4:$I$15,MATCH($C24,الإعدادات!$H$4:$H$15,0)),"غير معرف") -> مصاريف التشغيل | N24: =IFERROR(INDEX(الإعدادات!$J$4:$J$15,MATCH($C24,الإعدادات!$H$4:$H$15,0)),"غير معرف") -> مصروف | O24: =IFERROR(INDEX(الإعدادات!$K$4:$K$15,MATCH($C24,الإعدادات!$H$4:$H$15,0)),"غير معرف") -> قائمة الدخل | P24: =MONTH(A24) -> 8 | Q24: =YEAR(A24)&"-Q"&ROUNDUP(MONTH(A24)/3,0) -> 2026-Q3 | R24: =IF(AND(I24=1,F24>0),F24*الإعدادات!$N$4/(1+الإعدادات!$N$4),0) -> 0 | S24: =IF(AND(I24=1,G24>0),G24*الإعدادات!$N$4/(1+الإعدادات!$N$4),0) -> 0 | T24: =F24+G24-R24-S24 -> 2631
A25: 46265 | B25: رواتب وبدلات أغسطس 2026 | C25: الرواتب والبدلات | G25: =SUMIFS(الرواتب!$D$5:$D$22,الرواتب!$B$5:$B$22,"أغسطس 2026")+SUMIFS(الرواتب!$E$5:$E$22,الرواتب!$B$5:$B$22,"أغسطس 2026")-SUMIFS(الرواتب!$N$5:$N$22,الرواتب!$B$5:$B$22,"أغسطس 2026") -> 17233.333 | H25: البنك | I25: 0 | K25: قيد آلي — الرواتب | L25: =IFERROR(INDEX(الإعدادات!$G$4:$G$15,MATCH($C25,الإعدادات!$H$4:$H$15,0)),"غير معرف") -> 5100 | M25: =IFERROR(INDEX(الإعدادات!$I$4:$I$15,MATCH($C25,الإعدادات!$H$4:$H$15,0)),"غير معرف") -> مصاريف الموظفين | N25: =IFERROR(INDEX(الإعدادات!$J$4:$J$15,MATCH($C25,الإعدادات!$H$4:$H$15,0)),"غير معرف") -> مصروف | O25: =IFERROR(INDEX(الإعدادات!$K$4:$K$15,MATCH($C25,الإعدادات!$H$4:$H$15,0)),"غير معرف") -> قائمة الدخل | P25: =MONTH(A25) -> 8 | Q25: =YEAR(A25)&"-Q"&ROUNDUP(MONTH(A25)/3,0) -> 2026-Q3 | R25: =IF(AND(I25=1,F25>0),F25*الإعدادات!$N$4/(1+الإعدادات!$N$4),0) -> 0 | S25: =IF(AND(I25=1,G25>0),G25*الإعدادات!$N$4/(1+الإعدادات!$N$4),0) -> 0 | T25: =F25+G25-R25-S25 -> 17233.333
A26: 46265 | B26: عمولات وحوافز أغسطس 2026 | C26: العمولات والحوافز | G26: =SUMIFS(الرواتب!$G$5:$G$22,الرواتب!$B$5:$B$22,"أغسطس 2026")+SUMIFS(الرواتب!$H$5:$H$22,الرواتب!$B$5:$B$22,"أغسطس 2026")+SUMIFS(الرواتب!$J$5:$J$22,الرواتب!$B$5:$B$22,"أغسطس 2026")+SUMIFS(الرواتب!$K$5:$K$22,الرواتب!$B$5:$B$22,"أغسطس 2026") -> 21256 | H26: البنك | I26: 0 | K26: قيد آلي — الرواتب | L26: =IFERROR(INDEX(الإعدادات!$G$4:$G$15,MATCH($C26,الإعدادات!$H$4:$H$15,0)),"غير معرف") -> 5110 | M26: =IFERROR(INDEX(الإعدادات!$I$4:$I$15,MATCH($C26,الإعدادات!$H$4:$H$15,0)),"غير معرف") -> مصاريف الموظفين | N26: =IFERROR(INDEX(الإعدادات!$J$4:$J$15,MATCH($C26,الإعدادات!$H$4:$H$15,0)),"غير معرف") -> مصروف | O26: =IFERROR(INDEX(الإعدادات!$K$4:$K$15,MATCH($C26,الإعدادات!$H$4:$H$15,0)),"غير معرف") -> قائمة الدخل | P26: =MONTH(A26) -> 8 | Q26: =YEAR(A26)&"-Q"&ROUNDUP(MONTH(A26)/3,0) -> 2026-Q3 | R26: =IF(AND(I26=1,F26>0),F26*الإعدادات!$N$4/(1+الإعدادات!$N$4),0) -> 0 | S26: =IF(AND(I26=1,G26>0),G26*الإعدادات!$N$4/(1+الإعدادات!$N$4),0) -> 0 | T26: =F26+G26-R26-S26 -> 21256
A27: 46266 | B27: إيجار الشهر — قسط من الدفعة النصف سنوية | C27: الإيجار | D27: شركة الأفق العقارية | E27: 300112233400003 | G27: 11500 | H27: البنك | I27: 1 | K27: استحقاق شهري | L27: =IFERROR(INDEX(الإعدادات!$G$4:$G$15,MATCH($C27,الإعدادات!$H$4:$H$15,0)),"غير معرف") -> 5200 | M27: =IFERROR(INDEX(الإعدادات!$I$4:$I$15,MATCH($C27,الإعدادات!$H$4:$H$15,0)),"غير معرف") -> مصاريف الفرع | N27: =IFERROR(INDEX(الإعدادات!$J$4:$J$15,MATCH($C27,الإعدادات!$H$4:$H$15,0)),"غير معرف") -> مصروف | O27: =IFERROR(INDEX(الإعدادات!$K$4:$K$15,MATCH($C27,الإعدادات!$H$4:$H$15,0)),"غير معرف") -> قائمة الدخل | P27: =MONTH(A27) -> 9 | Q27: =YEAR(A27)&"-Q"&ROUNDUP(MONTH(A27)/3,0) -> 2026-Q3 | R27: =IF(AND(I27=1,F27>0),F27*الإعدادات!$N$4/(1+الإعدادات!$N$4),0) -> 0 | S27: =IF(AND(I27=1,G27>0),G27*الإعدادات!$N$4/(1+الإعدادات!$N$4),0) -> 1500 | T27: =F27+G27-R27-S27 -> 10000
A28: 46270 | B28: فاتورة كهرباء ومياه | C28: الكهرباء والمياه | D28: شركة الكهرباء | E28: 300000000100003 | G28: 1429 | H28: البنك | I28: 1 | K28: إدخال يدوي | L28: =IFERROR(INDEX(الإعدادات!$G$4:$G$15,MATCH($C28,الإعدادات!$H$4:$H$15,0)),"غير معرف") -> 5210 | M28: =IFERROR(INDEX(الإعدادات!$I$4:$I$15,MATCH($C28,الإعدادات!$H$4:$H$15,0)),"غير معرف") -> مصاريف الفرع | N28: =IFERROR(INDEX(الإعدادات!$J$4:$J$15,MATCH($C28,الإعدادات!$H$4:$H$15,0)),"غير معرف") -> مصروف | O28: =IFERROR(INDEX(الإعدادات!$K$4:$K$15,MATCH($C28,الإعدادات!$H$4:$H$15,0)),"غير معرف") -> قائمة الدخل | P28: =MONTH(A28) -> 9 | Q28: =YEAR(A28)&"-Q"&ROUNDUP(MONTH(A28)/3,0) -> 2026-Q3 | R28: =IF(AND(I28=1,F28>0),F28*الإعدادات!$N$4/(1+الإعدادات!$N$4),0) -> 0 | S28: =IF(AND(I28=1,G28>0),G28*الإعدادات!$N$4/(1+الإعدادات!$N$4),0) -> 186.3913 | T28: =F28+G28-R28-S28 -> 1242.6087
A29: 46275 | B29: رسوم تأشيرة موظف جديد | C29: تكاليف الموظفين (تأشيرات وتأمين) | D29: منصة حكومية | G29: 2000 | H29: البنك | I29: 0 | K29: إدخال يدوي | L29: =IFERROR(INDEX(الإعدادات!$G$4:$G$15,MATCH($C29,الإعدادات!$H$4:$H$15,0)),"غير معرف") -> 5120 | M29: =IFERROR(INDEX(الإعدادات!$I$4:$I$15,MATCH($C29,الإعدادات!$H$4:$H$15,0)),"غير معرف") -> مصاريف الموظفين | N29: =IFERROR(INDEX(الإعدادات!$J$4:$J$15,MATCH($C29,الإعدادات!$H$4:$H$15,0)),"غير معرف") -> مصروف | O29: =IFERROR(INDEX(الإعدادات!$K$4:$K$15,MATCH($C29,الإعدادات!$H$4:$H$15,0)),"غير معرف") -> قائمة الدخل | P29: =MONTH(A29) -> 9 | Q29: =YEAR(A29)&"-Q"&ROUNDUP(MONTH(A29)/3,0) -> 2026-Q3 | R29: =IF(AND(I29=1,F29>0),F29*الإعدادات!$N$4/(1+الإعدادات!$N$4),0) -> 0 | S29: =IF(AND(I29=1,G29>0),G29*الإعدادات!$N$4/(1+الإعدادات!$N$4),0) -> 0 | T29: =F29+G29-R29-S29 -> 2000
A30: 46279 | B30: شراء مستلزمات ومنتجات | C30: المستلزمات والأدوات | D30: شركة الإمداد التجارية | E30: 300554433200003 | G30: 3833 | H30: البنك | I30: 1 | K30: إدخال يدوي | L30: =IFERROR(INDEX(الإعدادات!$G$4:$G$15,MATCH($C30,الإعدادات!$H$4:$H$15,0)),"غير معرف") -> 5220 | M30: =IFERROR(INDEX(الإعدادات!$I$4:$I$15,MATCH($C30,الإعدادات!$H$4:$H$15,0)),"غير معرف") -> مصاريف التشغيل | N30: =IFERROR(INDEX(الإعدادات!$J$4:$J$15,MATCH($C30,الإعدادات!$H$4:$H$15,0)),"غير معرف") -> مصروف | O30: =IFERROR(INDEX(الإعدادات!$K$4:$K$15,MATCH($C30,الإعدادات!$H$4:$H$15,0)),"غير معرف") -> قائمة الدخل | P30: =MONTH(A30) -> 9 | Q30: =YEAR(A30)&"-Q"&ROUNDUP(MONTH(A30)/3,0) -> 2026-Q3 | R30: =IF(AND(I30=1,F30>0),F30*الإعدادات!$N$4/(1+الإعدادات!$N$4),0) -> 0 | S30: =IF(AND(I30=1,G30>0),G30*الإعدادات!$N$4/(1+الإعدادات!$N$4),0) -> 499.95652 | T30: =F30+G30-R30-S30 -> 3333.0435
A31: 46283 | B31: شراء مستلزمات ومنتجات | C31: المستلزمات والأدوات | D31: مؤسسة النخبة للمستلزمات | E31: 300998877600003 | G31: 4909 | H31: البنك | I31: 1 | K31: إدخال يدوي | L31: =IFERROR(INDEX(الإعدادات!$G$4:$G$15,MATCH($C31,الإعدادات!$H$4:$H$15,0)),"غير معرف") -> 5220 | M31: =IFERROR(INDEX(الإعدادات!$I$4:$I$15,MATCH($C31,الإعدادات!$H$4:$H$15,0)),"غير معرف") -> مصاريف التشغيل | N31: =IFERROR(INDEX(الإعدادات!$J$4:$J$15,MATCH($C31,الإعدادات!$H$4:$H$15,0)),"غير معرف") -> مصروف | O31: =IFERROR(INDEX(الإعدادات!$K$4:$K$15,MATCH($C31,الإعدادات!$H$4:$H$15,0)),"غير معرف") -> قائمة الدخل | P31: =MONTH(A31) -> 9 | Q31: =YEAR(A31)&"-Q"&ROUNDUP(MONTH(A31)/3,0) -> 2026-Q3 | R31: =IF(AND(I31=1,F31>0),F31*الإعدادات!$N$4/(1+الإعدادات!$N$4),0) -> 0 | S31: =IF(AND(I31=1,G31>0),G31*الإعدادات!$N$4/(1+الإعدادات!$N$4),0) -> 640.30435 | T31: =F31+G31-R31-S31 -> 4268.6957
A32: 46290 | B32: حملة إعلانية على السوشيال | C32: التسويق | D32: وكالة ومضة | E32: 300776655400003 | G32: 1643 | H32: البنك | I32: 1 | K32: إدخال يدوي | L32: =IFERROR(INDEX(الإعدادات!$G$4:$G$15,MATCH($C32,الإعدادات!$H$4:$H$15,0)),"غير معرف") -> 5300 | M32: =IFERROR(INDEX(الإعدادات!$I$4:$I$15,MATCH($C32,الإعدادات!$H$4:$H$15,0)),"غير معرف") -> مصاريف التشغيل | N32: =IFERROR(INDEX(الإعدادات!$J$4:$J$15,MATCH($C32,الإعدادات!$H$4:$H$15,0)),"غير معرف") -> مصروف | O32: =IFERROR(INDEX(الإعدادات!$K$4:$K$15,MATCH($C32,الإعدادات!$H$4:$H$15,0)),"غير معرف") -> قائمة الدخل | P32: =MONTH(A32) -> 9 | Q32: =YEAR(A32)&"-Q"&ROUNDUP(MONTH(A32)/3,0) -> 2026-Q3 | R32: =IF(AND(I32=1,F32>0),F32*الإعدادات!$N$4/(1+الإعدادات!$N$4),0) -> 0 | S32: =IF(AND(I32=1,G32>0),G32*الإعدادات!$N$4/(1+الإعدادات!$N$4),0) -> 214.30435 | T32: =F32+G32-R32-S32 -> 1428.6957
A33: 46293 | B33: عمولة بوابات الدفع | C33: رسوم بوابات الدفع | D33: بنك محلي | G33: 890 | H33: البنك | I33: 1 | K33: إدخال يدوي | L33: =IFERROR(INDEX(الإعدادات!$G$4:$G$15,MATCH($C33,الإعدادات!$H$4:$H$15,0)),"غير معرف") -> 5400 | M33: =IFERROR(INDEX(الإعدادات!$I$4:$I$15,MATCH($C33,الإعدادات!$H$4:$H$15,0)),"غير معرف") -> مصاريف التشغيل | N33: =IFERROR(INDEX(الإعدادات!$J$4:$J$15,MATCH($C33,الإعدادات!$H$4:$H$15,0)),"غير معرف") -> مصروف | O33: =IFERROR(INDEX(الإعدادات!$K$4:$K$15,MATCH($C33,الإعدادات!$H$4:$H$15,0)),"غير معرف") -> قائمة الدخل | P33: =MONTH(A33) -> 9 | Q33: =YEAR(A33)&"-Q"&ROUNDUP(MONTH(A33)/3,0) -> 2026-Q3 | R33: =IF(AND(I33=1,F33>0),F33*الإعدادات!$N$4/(1+الإعدادات!$N$4),0) -> 0 | S33: =IF(AND(I33=1,G33>0),G33*الإعدادات!$N$4/(1+الإعدادات!$N$4),0) -> 116.08696 | T33: =F33+G33-R33-S33 -> 773.91304
A34: 46295 | B34: دفعة أولى من ضريبة الربع الثالث | C34: ضريبة القيمة المضافة المسددة | D34: هيئة الزكاة والضريبة | G34: 6000 | H34: البنك | I34: 0 | J34: 2026-Q3 | K34: سداد على دفعات | L34: =IFERROR(INDEX(الإعدادات!$G$4:$G$15,MATCH($C34,الإعدادات!$H$4:$H$15,0)),"غير معرف") -> 2300 | M34: =IFERROR(INDEX(الإعدادات!$I$4:$I$15,MATCH($C34,الإعدادات!$H$4:$H$15,0)),"غير معرف") -> الالتزامات | N34: =IFERROR(INDEX(الإعدادات!$J$4:$J$15,MATCH($C34,الإعدادات!$H$4:$H$15,0)),"غير معرف") -> تسوية | O34: =IFERROR(INDEX(الإعدادات!$K$4:$K$15,MATCH($C34,الإعدادات!$H$4:$H$15,0)),"غير معرف") -> المركز المالي | P34: =MONTH(A34) -> 9 | Q34: =YEAR(A34)&"-Q"&ROUNDUP(MONTH(A34)/3,0) -> 2026-Q3 | R34: =IF(AND(I34=1,F34>0),F34*الإعدادات!$N$4/(1+الإعدادات!$N$4),0) -> 0 | S34: =IF(AND(I34=1,G34>0),G34*الإعدادات!$N$4/(1+الإعدادات!$N$4),0) -> 0 | T34: =F34+G34-R34-S34 -> 6000
A35: 46295 | B35: إيرادات سبتمبر 2026 — من اليومية | C35: مبيعات الخدمات | F35: =SUMIFS(اليومية!$V$5:$V$96,اليومية!$C$5:$C$96,"سبتمبر 2026") -> 118417 | H35: البنك | I35: 1 | K35: قيد آلي — اليومية | L35: =IFERROR(INDEX(الإعدادات!$G$4:$G$15,MATCH($C35,الإعدادات!$H$4:$H$15,0)),"غير معرف") -> 4100 | M35: =IFERROR(INDEX(الإعدادات!$I$4:$I$15,MATCH($C35,الإعدادات!$H$4:$H$15,0)),"غير معرف") -> الإيرادات | N35: =IFERROR(INDEX(الإعدادات!$J$4:$J$15,MATCH($C35,الإعدادات!$H$4:$H$15,0)),"غير معرف") -> إيراد | O35: =IFERROR(INDEX(الإعدادات!$K$4:$K$15,MATCH($C35,الإعدادات!$H$4:$H$15,0)),"غير معرف") -> قائمة الدخل | P35: =MONTH(A35) -> 9 | Q35: =YEAR(A35)&"-Q"&ROUNDUP(MONTH(A35)/3,0) -> 2026-Q3 | R35: =IF(AND(I35=1,F35>0),F35*الإعدادات!$N$4/(1+الإعدادات!$N$4),0) -> 15445.696 | S35: =IF(AND(I35=1,G35>0),G35*الإعدادات!$N$4/(1+الإعدادات!$N$4),0) -> 0 | T35: =F35+G35-R35-S35 -> 102971.3
